Workbook

Sheet Rent Roll
A1: Property | B1: Suite | C1: Tenant | D1: SF | E1: Lease Start | F1: Lease End | G1: Annual Rent | H1: Rent PSF | I1: Market Rent PSF | J1: Loss-to-Lease PSF | K1: Status | L1: Notes
A2: Carrollton | B2: 100 | C2: Titan Glass LLC | D2: 2600 | E2: Oct-2023 | F2: Mar-2027 | G2: 38926 | H2: =IF(D2=0,0,G2/D2) -> 14.971538 | I2: 18 | J2: =IF(G2=0,0,I2-H2) -> 3.0284615 | K2: Occupied | L2: Shop; Guarantor: Adren Savitch
A3: Carrollton | B3: 104 | C3: Fluonics Inc. | D3: 2600 | E3: Oct-2024 | F3: Mar-2028 | G3: 42640 | H3: =IF(D3=0,0,G3/D3) -> 16.4 | I3: 18 | J3: =IF(G3=0,0,I3-H3) -> 1.6 | K3: Occupied | L3: Shop; Guarantor: Fluonics Co. Ltd (Korea)
A4: Carrollton | B4: 108 | C4: Bath Touch Metals Inc. | D4: 2600 | E4: Dec-2023 | F4: May-2027 | G4: 40291 | H4: =IF(D4=0,0,G4/D4) -> 15.496538 | I4: 18 | J4: =IF(G4=0,0,I4-H4) -> 2.5034615 | K4: Occupied | L4: Shop; assumed to vacate at expiration
A5: Carrollton | B5: 112 | C5: VACANT | D5: 2600 | G5: 0 | H5: =IF(D5=0,0,G5/D5) -> 0 | I5: 18 | J5: =IF(G5=0,0,I5-H5) -> 0 | K5: Vacant | L5: Shop; future lease-up Jan-2027 in OM
A6: Carrollton | B6: 116 | C6: Vivax Systems Inc. | D6: 2600 | E6: Mar-2025 | F6: Sep-2028 | G6: 45305 | H6: =IF(D6=0,0,G6/D6) -> 17.425 | I6: 18 | J6: =IF(G6=0,0,I6-H6) -> 0.575 | K6: Occupied | L6: Shop; Guarantor: Haresh Busa
A7: Carrollton | B7: 120 | C7: KJLux Auto LLC | D7: 2600 | E7: Oct-2023 | F7: Sep-2027 | G7: 40291 | H7: =IF(D7=0,0,G7/D7) -> 15.496538 | I7: 18 | J7: =IF(G7=0,0,I7-H7) -> 2.5034615 | K7: Occupied | L7: Shop; Guarantor: Kristopher Johnson / Isaac Wilke
A8: Carrollton | B8: 124 | C8: CervComm Technology Group LLC | D8: 2600 | E8: Oct-2023 | F8: Sep-2027 | G8: 40291 | H8: =IF(D8=0,0,G8/D8) -> 15.496538 | I8: 18 | J8: =IF(G8=0,0,I8-H8) -> 2.5034615 | K8: Occupied | L8: Shop; Guarantor: Jacob/Christine Cervantes
A9: Carrollton | B9: 128 | C9: FirstCall Mechanical Group Texas LLC | D9: 2600 | E9: Oct-2023 | F9: Mar-2027 | G9: 40291 | H9: =IF(D9=0,0,G9/D9) -> 15.496538 | I9: 18 | J9: =IF(G9=0,0,I9-H9) -> 2.5034615 | K9: Occupied | L9: Shop
A10: Carrollton | B10: 132 | C10: The Vicla Shop LLC | D10: 2600 | E10: Dec-2023 | F10: Nov-2028 | G10: 40291 | H10: =IF(D10=0,0,G10/D10) -> 15.496538 | I10: 18 | J10: =IF(G10=0,0,I10-H10) -> 2.5034615 | K10: Occupied | L10: Shop; Guarantor: Luth Wende / Rodney Ramos
A11: Carrollton | B11: 136 | C11: March Motorsports LLC | D11: 4525 | E11: Dec-2023 | F11: May-2027 | G11: 70123 | H11: =IF(D11=0,0,G11/D11) -> 15.496796 | I11: 18 | J11: =IF(G11=0,0,I11-H11) -> 2.5032044 | K11: Occupied | L11: Shop; Guarantor: Dalton March
A12: Carrollton | B12: 200 | C12: Wada Precision Dental Laboratories USA | D12: 1870 | E12: Nov-2023 | F12: Oct-2028 | G12: 28979 | H12: =IF(D12=0,0,G12/D12) -> 15.496791 | I12: 16 | J12: =IF(G12=0,0,I12-H12) -> 0.50320856 | K12: Occupied | L12: Studio; Guarantor: Takeshi Kutsumizu
A13: Carrollton | B13: 204 | C13: J. Auto Solutions LLC | D13: 1870 | E13: Mar-2026 | F13: Feb-2027 | G13: 29920 | H13: =IF(D13=0,0,G13/D13) -> 16 | I13: 16 | J13: =IF(G13=0,0,I13-H13) -> 0 | K13: Occupied | L13: Studio; Guarantor: Xuan Luo
A14: Carrollton | B14: 208 | C14: LK Tools Inc. | D14: 1870 | E14: Jul-2025 | F14: Dec-2028 | G14: 26180 | H14: =IF(D14=0,0,G14/D14) -> 14 | I14: 16 | J14: =IF(G14=0,0,I14-H14) -> 2 | K14: Occupied | L14: Studio; Guarantor: Justin Baucum
A15: Carrollton | B15: 212 | C15: Isembard Corporation | D15: 3230 | E15: Jan-2025 | F15: Dec-2029 | G15: 56283 | H15: =IF(D15=0,0,G15/D15) -> 17.425077 | I15: 16 | J15: =IF(G15=0,0,I15-H15) -> -1.4250774 | K15: Occupied | L15: Studio; Guarantor: Sean Pae
A16: Carrollton | B16: 220 | C16: Cryofuture Inc. | D16: 3230 | E16: Apr-2024 | F16: Sep-2027 | G16: 50054 | H16: =IF(D16=0,0,G16/D16) -> 15.496594 | I16: 16 | J16: =IF(G16=0,0,I16-H16) -> 0.50340557 | K16: Occupied | L16: Studio; assumed to vacate; Guarantor: Angel Naomi Baker
A17: Carrollton | B17: 228 | C17: MD Management Holdings LLC | D17: 1870 | E17: Aug-2025 | F17: Jul-2027 | G17: 26180 | H17: =IF(D17=0,0,G17/D17) -> 14 | I17: 16 | J17: =IF(G17=0,0,I17-H17) -> 2 | K17: Occupied | L17: Studio; Guarantor: Micah Driver
... A19: Carrollton | B19: 236 | C19: Republic RX LLC | D19: 1870 | E19: Aug-2024 | F19: Feb-2028 | G19: 30668 | H19: =IF(D19=0,0,G19/D19) -> 16.4 | I19: 16 | J19: =IF(G19=0,0,I19-H19) -> -0.4 | K19: Occupied | L19: Studio; Guarantor: Tung Nguyen
A20: Carrollton | B20: 240 | C20: VACANT | D20: 1870 | G20: 0 | H20: =IF(D20=0,0,G20/D20) -> 0 | I20: 16 | J20: =IF(G20=0,0,I20-H20) -> 0 | K20: Vacant | L20: Studio; future lease-up Jul-2026 in OM
A21: Carrollton | B21: 300 | C21: VACANT | D21: 2580 | G21: 0 | H21: =IF(D21=0,0,G21/D21) -> 0 | I21: 16 | J21: =IF(G21=0,0,I21-H21) -> 0 | K21: Vacant | L21: Studio; future lease-up Nov-2026 in OM
A22: Carrollton | B22: 304 | C22: Jeremy Brewer & Thien Hoang | D22: 2720 | E22: Aug-2025 | F22: Jan-2029 | G22: 38080 | H22: =IF(D22=0,0,G22/D22) -> 14 | I22: 16 | J22: =IF(G22=0,0,I22-H22) -> 2 | K22: Occupied | L22: Studio
A23: Carrollton | B23: 316 | C23: CS Tuning Club LLC | D23: 3230 | E23: Jan-2026 | F23: Jul-2029 | G23: 45220 | H23: =IF(D23=0,0,G23/D23) -> 14 | I23: 16 | J23: =IF(G23=0,0,I23-H23) -> 2 | K23: Occupied | L23: Studio; Guarantor: Hsi (Sean) Chou
A24: Carrollton | B24: 320 | C24: Horvez Holdings Inc. | D24: 1870 | E24: May-2025 | F24: Oct-2028 | G24: 26835 | H24: =IF(D24=0,0,G24/D24) -> 14.350267 | I24: 16 | J24: =IF(G24=0,0,I24-H24) -> 1.6497326 | K24: Occupied | L24: Studio; Guarantor: Aixa Alvarez
A25: Carrollton | B25: 324 | C25: Horvez Holdings Inc. | D25: 1870 | E25: Dec-2025 | F25: Oct-2028 | G25: 26180 | H25: =IF(D25=0,0,G25/D25) -> 14 | I25: 16 | J25: =IF(G25=0,0,I25-H25) -> 2 | K25: Occupied | L25: Studio; Guarantor: Aixa Alvarez
A26: Carrollton | B26: 328 | C26: Delio LLC | D26: 1870 | E26: Nov-2025 | F26: May-2029 | G26: 29920 | H26: =IF(D26=0,0,G26/D26) -> 16 | I26: 16 | J26: =IF(G26=0,0,I26-H26) -> 0 | K26: Occupied | L26: Studio; Guarantor: Blue Swan Health
A27: Carrollton | B27: 332 | C27: VACANT | D27: 1870 | G27: 0 | H27: =IF(D27=0,0,G27/D27) -> 0 | I27: 16 | J27: =IF(G27=0,0,I27-H27) -> 0 | K27: Vacant | L27: Studio; future lease-up Sep-2026 in OM
A28: Carrollton | B28: 336 | C28: TMII Enterprises LLC | D28: 1870 | E28: Aug-2025 | F28: Nov-2027 | G28: 26180 | H28: =IF(D28=0,0,G28/D28) -> 14 | I28: 16 | J28: =IF(G28=0,0,I28-H28) -> 2 | K28: Occupied | L28: Studio; Guarantor: Joseph McCusker
A29: Carrollton | B29: 340 | C29: TMII Enterprises LLC | D29: 1870 | E29: Jun-2024 | F29: Nov-2027 | G29: 30668 | H29: =IF(D29=0,0,G29/D29) -> 16.4 | I29: 16 | J29: =IF(G29=0,0,I29-H29) -> -0.4 | K29: Occupied | L29: Studio; Guarantor: Joseph McCusker
A30: Carrollton | B30: 400 | C30: Egnite Electric LLC | D30: 12805 | E30: Nov-2025 | F30: Oct-2030 | G30: 212819 | H30: =IF(D30=0,0,G30/D30) -> 16.619992 | I30: 18 | J30: =IF(G30=0,0,I30-H30) -> 1.3800078 | K30: Occupied | L30: Shop; Guarantor: Jazziel Perea Perez
A31: Carrollton | B31: 412 | C31: Egnite Electric LLC | D31: 2600 | E31: Feb-2026 | F31: Oct-2030 | G31: 46800 | H31: =IF(D31=0,0,G31/D31) -> 18 | I31: 18 | J31: =IF(G31=0,0,I31-H31) -> 0 | K31: Occupied | L31: Shop; Guarantor: Jazziel Perea Perez
A32: Carrollton | B32: 416 | C32: Egnite Electric LLC | D32: 2600 | E32: Apr-2025 | F32: Mar-2029 | G32: 47970 | H32: =IF(D32=0,0,G32/D32) -> 18.45 | I32: 18 | J32: =IF(G32=0,0,I32-H32) -> -0.45 | K32: Occupied | L32: Shop; Guarantor: Richard Simon
A33: Carrollton | B33: 420 | C33: DT Creations Inc. | D33: 3450 | E33: Feb-2025 | F33: Jul-2028 | G33: 56580 | H33: =IF(D33=0,0,G33/D33) -> 16.4 | I33: 18 | J33: =IF(G33=0,0,I33-H33) -> 1.6 | K33: Occupied | L33: Shop; Guarantor: Jazziel Ruben Perea
A34: Carrollton | B34: 424 | C34: Metro Elevator DFW Inc. | D34: 2600 | E34: Jan-2026 | F34: Oct-2028 | G34: 46800 | H34: =IF(D34=0,0,G34/D34) -> 18 | I34: 18 | J34: =IF(G34=0,0,I34-H34) -> 0 | K34: Occupied | L34: Shop; Guarantor: Brad Hager
A35: Carrollton | B35: 428 | C35: Metro Elevator DFW Inc. | D35: 2600 | E35: May-2025 | F35: Oct-2028 | G35: 47970 | H35: =IF(D35=0,0,G35/D35) -> 18.45 | I35: 18 | J35: =IF(G35=0,0,I35-H35) -> -0.45 | K35: Occupied | L35: Shop; Guarantor: Metro Elevator Holdings
A36: Carrollton | B36: 432 | C36: Metro Elevator DFW Inc. | D36: 4525 | E36: May-2025 | F36: Apr-2028 | G36: 83486 | H36: =IF(D36=0,0,G36/D36) -> 18.449945 | I36: 18 | J36: =IF(G36=0,0,I36-H36) -> -0.44994475 | K36: Occupied | L36: Shop
A37: Carrollton | B37: 440 | C37: Prime Facility Maintenance Inc. | D37: 3450 | E37: Mar-2025 | F37: Aug-2028 | G37: 56580 | H37: =IF(D37=0,0,G37/D37) -> 16.4 | I37: 18 | J37: =IF(G37=0,0,I37-H37) -> 1.6 | K37: Occupied | L37: Shop; Guarantor: Seferino Marquez
A38: Frisco | B38: 101 | C38: Legacy Respiratory Care & Medical Equipment Inc | D38: 2600 | E38: Apr-2025 | F38: Sep-2028 | G38: 50635 | H38: =IF(D38=0,0,G38/D38) -> 19.475 | I38: 19 | J38: =IF(G38=0,0,I38-H38) -> -0.475 | K38: Occupied | L38: Guarantor: Anthony Aguilar / Primrose Homehealth
A39: Frisco | B39: 102 | C39: Redden Companies LLC | D39: 2600 | E39: Apr-2025 | F39: Sep-2028 | G39: 47970 | H39: =IF(D39=0,0,G39/D39) -> 18.45 | I39: 19 | J39: =IF(G39=0,0,I39-H39) -> 0.55 | K39: Occupied | L39: Guarantor: Brooke Redden
A40: Frisco | B40: 103 | C40: Titan Glass LLC | D40: 2600 | E40: Apr-2025 | F40: Mar-2029 | G40: 45305 | H40: =IF(D40=0,0,G40/D40) -> 17.425 | I40: 19 | J40: =IF(G40=0,0,I40-H40) -> 1.575 | K40: Occupied
A41: Frisco | B41: 104 | C41: Axis Water Technologies | D41: 2600 | E41: Apr-2025 | F41: Sep-2028 | G41: 41974 | H41: =IF(D41=0,0,G41/D41) -> 16.143846 | I41: 19 | J41: =IF(G41=0,0,I41-H41) -> 2.8561538 | K41: Occupied | L41: Guarantor: Adren Savitch
...

Sheet Summary
A1: Property | B1: Total SF | C1: Occupied SF | D1: Vacant SF | E1: Occupancy % | F1: # Units | G1: Annual In-Place Rent | H1: Avg In-Place PSF | I1: Avg Market PSF | J1: LTL %
A2: Carrollton | B2: =SUMIF('Rent Roll'!A:A,A2,'Rent Roll'!D:D) -> 101855 | C2: =SUMIFS('Rent Roll'!D:D,'Rent Roll'!A:A,A2,'Rent Roll'!K:K,"Occupied") -> 92935 | D2: =SUMIFS('Rent Roll'!D:D,'Rent Roll'!A:A,A2,'Rent Roll'!K:K,"Vacant") -> 8920 | E2: =IF(B2=0,0,C2/B2) -> 0.91242453 | F2: =COUNTIF('Rent Roll'!A:A,A2) -> 36 | G2: =SUMIF('Rent Roll'!A:A,A2,'Rent Roll'!G:G) -> 1494981 | H2: =IF(C2=0,0,G2/C2) -> 16.086308 | I2: =IF(B2=0,0,SUMPRODUCT(('Rent Roll'!A2:A163=A2)*'Rent Roll'!D2:D163*'Rent Roll'!I2:I163)/B2) -> 17.228315 | J2: =IF(H2=0,0,I2/H2-1) -> 0.070992496
A3: Frisco | B3: =SUMIF('Rent Roll'!A:A,A3,'Rent Roll'!D:D) -> 74600 | C3: =SUMIFS('Rent Roll'!D:D,'Rent Roll'!A:A,A3,'Rent Roll'!K:K,"Occupied") -> 74600 | D3: =SUMIFS('Rent Roll'!D:D,'Rent Roll'!A:A,A3,'Rent Roll'!K:K,"Vacant") -> 0 | E3: =IF(B3=0,0,C3/B3) -> 1 | F3: =COUNTIF('Rent Roll'!A:A,A3) -> 28 | G3: =SUMIF('Rent Roll'!A:A,A3,'Rent Roll'!G:G) -> 1341677 | H3: =IF(C3=0,0,G3/C3) -> 17.984946 | I3: =IF(B3=0,0,SUMPRODUCT(('Rent Roll'!A2:A163=A3)*'Rent Roll'!D2:D163*'Rent Roll'!I2:I163)/B3) -> 19 | J3: =IF(H3=0,0,I3/H3-1) -> 0.056439068
A4: Mesquite | B4: =SUMIF('Rent Roll'!A:A,A4,'Rent Roll'!D:D) -> 50750 | C4: =SUMIFS('Rent Roll'!D:D,'Rent Roll'!A:A,A4,'Rent Roll'!K:K,"Occupied") -> 35470 | D4: =SUMIFS('Rent Roll'!D:D,'Rent Roll'!A:A,A4,'Rent Roll'!K:K,"Vacant") -> 15280 | E4: =IF(B4=0,0,C4/B4) -> 0.69891626 | F4: =COUNTIF('Rent Roll'!A:A,A4) -> 22 | G4: =SUMIF('Rent Roll'!A:A,A4,'Rent Roll'!G:G) -> 538159 | H4: =IF(C4=0,0,G4/C4) -> 15.17223 | I4: =IF(B4=0,0,SUMPRODUCT(('Rent Roll'!A2:A163=A4)*'Rent Roll'!D2:D163*'Rent Roll'!I2:I163)/B4) -> 16 | J4: =IF(H4=0,0,I4/H4-1) -> 0.054558225
A5: Lewisville | B5: =SUMIF('Rent Roll'!A:A,A5,'Rent Roll'!D:D) -> 69500 | C5: =SUMIFS('Rent Roll'!D:D,'Rent Roll'!A:A,A5,'Rent Roll'!K:K,"Occupied") -> 69500 | D5: =SUMIFS('Rent Roll'!D:D,'Rent Roll'!A:A,A5,'Rent Roll'!K:K,"Vacant") -> 0 | E5: =IF(B5=0,0,C5/B5) -> 1 | F5: =COUNTIF('Rent Roll'!A:A,A5) -> 28 | G5: =SUMIF('Rent Roll'!A:A,A5,'Rent Roll'!G:G) -> 1084026 | H5: =IF(C5=0,0,G5/C5) -> 15.597496 | I5: =IF(B5=0,0,SUMPRODUCT(('Rent Roll'!A2:A163=A5)*'Rent Roll'!D2:D163*'Rent Roll'!I2:I163)/B5) -> 18 | J5: =IF(H5=0,0,I5/H5-1) -> 0.15403136
A6: Roanoke | B6: =SUMIF('Rent Roll'!A:A,A6,'Rent Roll'!D:D) -> 51595 | C6: =SUMIFS('Rent Roll'!D:D,'Rent Roll'!A:A,A6,'Rent Roll'!K:K,"Occupied") -> 30245 | D6: =SUMIFS('Rent Roll'!D:D,'Rent Roll'!A:A,A6,'Rent Roll'!K:K,"Vacant") -> 21350 | E6: =IF(B6=0,0,C6/B6) -> 0.58620021 | F6: =COUNTIF('Rent Roll'!A:A,A6) -> 18 | G6: =SUMIF('Rent Roll'!A:A,A6,'Rent Roll'!G:G) -> 512730 | H6: =IF(C6=0,0,G6/C6) -> 16.952554 | I6: =IF(B6=0,0,SUMPRODUCT(('Rent Roll'!A2:A163=A6)*'Rent Roll'!D2:D163*'Rent Roll'!I2:I163)/B6) -> 17 | J6: =IF(H6=0,0,I6/H6-1) -> 0.002798744
A7: Plano | B7: =SUMIF('Rent Roll'!A:A,A7,'Rent Roll'!D:D) -> 82250 | C7: =SUMIFS('Rent Roll'!D:D,'Rent Roll'!A:A,A7,'Rent Roll'!K:K,"Occupied") -> 79650 | D7: =SUMIFS('Rent Roll'!D:D,'Rent Roll'!A:A,A7,'Rent Roll'!K:K,"Vacant") -> 2600 | E7: =IF(B7=0,0,C7/B7) -> 0.96838906 | F7: =COUNTIF('Rent Roll'!A:A,A7) -> 30 | G7: =SUMIF('Rent Roll'!A:A,A7,'Rent Roll'!G:G) -> 1318936 | H7: =IF(C7=0,0,G7/C7) -> 16.559146 | I7: =IF(B7=0,0,SUMPRODUCT(('Rent Roll'!A2:A163=A7)*'Rent Roll'!D2:D163*'Rent Roll'!I2:I163)/B7) -> 19 | J7: =IF(H7=0,0,I7/H7-1) -> 0.14740215
A8: Portfolio | B8: =SUM(B2:B7) -> 430550 | C8: =SUM(C2:C7) -> 382400 | D8: =SUM(D2:D7) -> 48150 | E8: =IF(B8=0,0,C8/B8) -> 0.8881663 | F8: =SUM(F2:F7) -> 162 | G8: =SUM(G2:G7) -> 6290509 | H8: =IF(C8=0,0,G8/C8) -> 16.450076 | I8: =IF(B8=0,0,SUMPRODUCT('Rent Roll'!D2:D163,'Rent Roll'!I2:I163)/B8) -> 17.826164 | J8: =IF(H8=0,0,I8/H8-1) -> 0.083652403
