Workbook
Name AnalysisStart: 'Assumptions'!$B5
Name HoldMonths: 'Assumptions'!$B6
Name ProjMonths: 'Assumptions'!$B7
Name FYEndMonth: 'Assumptions'!$B8
Name GrowthMarketRent: 'Assumptions'!$B10
Name EscalatorInLease: 'Assumptions'!$B11
Name GrowthOpEx: 'Assumptions'!$B12
Name GrowthRETax: 'Assumptions'!$B13
Name CPI: 'Assumptions'!$B14
Name GrowthOther: 'Assumptions'!$B15
Name Retention: 'Assumptions'!$B17
Name LeaseTermMonths: 'Assumptions'!$B18
Name TINew: 'Assumptions'!$B19
Name TIRenewal: 'Assumptions'!$B20
Name LCNew: 'Assumptions'!$B21
Name LCRenewal: 'Assumptions'!$B22
Name DowntimeNew: 'Assumptions'!$B23
Name DowntimeRenewal: 'Assumptions'!$B24
Name FreeRentNew: 'Assumptions'!$B25
Name FreeRentRenewal: 'Assumptions'!$B26
Name GeneralVacancy: 'Assumptions'!$B28
Name CreditLoss: 'Assumptions'!$B29
Name RecoveryPct: 'Assumptions'!$B31
Name MgmtFeePct: 'Assumptions'!$B32
Name ReservesPSF: 'Assumptions'!$B33
Name ReassessTaxes: 'Assumptions'!$B35
Name ParkingRentMonthly: 'Assumptions'!$B37
Name ParkingUtilStab: 'Assumptions'!$B38
Name TURentGrowth: 'Assumptions'!$B39
Name PricingMode: 'Assumptions'!$B41
Name PricePerSF: 'Assumptions'!$B42
Name TargetCap: 'Assumptions'!$B43
Name PricePriceDirect: 'Assumptions'!$B44
Name ExitCap: 'Assumptions'!$B45
Name AcqCostPct: 'Assumptions'!$B47
Name DispCostPct: 'Assumptions'!$B48
Name LTV: 'Assumptions'!$B50
Name SOFR: 'Assumptions'!$B51
Name LoanSpreadBps: 'Assumptions'!$B52
Name LoanRate: 'Assumptions'!$B53
Name LoanTermMonths: 'Assumptions'!$B54
Name LoanIOMonths: 'Assumptions'!$B55
Name LoanAmortMonths: 'Assumptions'!$B56
Name LoanOrigFeePct: 'Assumptions'!$B57
Name WaterfallOn: 'Assumptions'!$B59
Name PrefReturn: 'Assumptions'!$B60
Name Tier1GPSplit: 'Assumptions'!$B61
Name Tier1Hurdle: 'Assumptions'!$B62
Name Tier2GPSplit: 'Assumptions'!$B63
Name Tier2Hurdle: 'Assumptions'!$B64
Name Tier3GPSplit: 'Assumptions'!$B65
Name InPlaceNOI: 'Assumptions'!$B67
Name PortfolioSF: 'Assumptions'!$B68
Name PurchasePrice: 'Assumptions'!$B69
Name PricePerSFImplied: 'Assumptions'!$B70
Name CapInPlace: 'Assumptions'!$B71

Sheet Assumptions
A1: DFW MODERN MULTI-TENANT PORTFOLIO — UNDERWRITING ASSUMPTIONS
A2: All yellow cells are user inputs. Orange = estimated (Plano OM incomplete).
A4: MODEL TIMING
A5: Analysis Start Date | B5: 46143 | C5: May 1, 2026 — matches OM
A6: Hold Period (months) | B6: 60 | C6: 5-year hold (matches loan term)
A7: Projection Period (months) | B7: 120 | C7: Always project 10 yrs for exit cap / reversion math
A8: Fiscal Year End Month | B8: 4 | C8: April (matches OM Argus FYE 4/30)
A9: GROWTH RATES
A10: Market Rent Growth | B10: 0.03 | C10: CBRE/Argus assumption
A11: In-Lease Rent Escalator | B11: 0.025 | C11: Typical 2.5% annual bumps
A12: Operating Expense Growth | B12: 0.03
A13: RE Tax Growth | B13: 0.03 | C13: Applied to reassessed base
A14: CPI | B14: 0.03
A15: Other Revenue Growth | B15: 0.03 | C15: Ancillary income
A16: LEASING ASSUMPTIONS (PORTFOLIO DEFAULTS — overrideable on MLA tab)
A17: Renewal Probability (Retention) | B17: 0.75 | C17: CBRE default 75%
A18: New Lease Term (months) | B18: 42 | C18: 3 yrs 6 months
A19: TI — New ($/SF) | B19: 1.5
A20: TI — Renewal ($/SF) | B20: 0
A21: LC — New (% of base rent) | B21: 0.0675
A22: LC — Renewal (%) | B22: 0.0325
A23: Downtime — New (months) | B23: 3
A24: Downtime — Renewal (months) | B24: 0 | C24: Typically zero
A25: Free Rent — New (months) | B25: 0
A26: Free Rent — Renewal (months) | B26: 0
A27: VACANCY & CREDIT
A28: General Vacancy | B28: 0.02 | C28: Beyond lease-up vacancy
A29: Credit Loss | B29: 0.01
A30: REIMBURSEMENTS & MANAGEMENT
A31: Recovery % (NNN Pass-through) | B31: 1 | C31: 100% NNN all leases
A32: Management Fee (% of EGR) | B32: 0.04 | C32: 4% per OM; 5% cap per lease
A33: Capital Reserves ($/SF) | B33: 0.2
A34: REAL ESTATE TAXES
A35: Reassess Taxes at Purchase? | B35: TRUE | C35: TRUE = taxes reset to Purchase Price × millage
A36: ANCILLARY INCOME
A37: Parking Rent $/Stall/Month (new) | B37: 165 | C37: Secured parking
A38: Parking Stabilized Utilization | B38: 0.9 | C38: Target year 3+
A39: Tenant Upgrade Rent Growth | B39: 0.025
A40: PRICING
A41: Pricing Mode | B41: price_psf | C41: price_psf | cap_on_inplace | cap_on_y1 | price_direct
...

Sheet Property Data
A1: PROPERTY DATA
B2: Carrollton | C2: Frisco | D2: Lewisville | E2: Mesquite | F2: Plano | G2: Roanoke | H2: Portfolio
A3: Property ID | B3: CAR | C3: FRI | D3: LEW | E3: MES | F3: PLA | G3: ROA
A4: Total SF | B4: 101855 | C4: 74600 | D4: 69500 | E4: 50750 | F4: 82250 | G4: 51595 | H4: =SUM(B4:G4)
A5: Office SF | B5: 43046 | C5: 37300 | D5: 31960 | E5: 21225 | F5: 41125 | G5: 18465 | H5: =SUM(B5:G5)
A6: Office % | B6: 0.42 | C6: 0.5 | D6: 0.46 | E6: 0.42 | F6: 0.5 | G6: 0.36
A7: Land Acres | B7: 7.47 | C7: 5.16 | D7: 4.5 | E7: 3.45 | F7: 5.5 | G7: 3.25 | H7: =SUM(B7:G7)
A8: # Buildings | B8: 4 | C8: 3 | D8: 3 | E8: 2 | F8: 3 | G8: 2 | H8: =SUM(B8:G8)
A9: # Units | B9: 36 | C9: 28 | D9: 28 | E9: 22 | F9: 30 | G9: 18 | H9: =SUM(B9:G9)
A10: Year Built | B10: 2023 | C10: 2024 | D10: 2023 | E10: 2022 | F10: 2023 | G10: 2025 | H10: =SUM(B10:G10)
A11: Parking Spaces | B11: 192 | C11: 161 | D11: 127 | E11: 138 | F11: 178 | G11: 131 | H11: =SUM(B11:G11)
A12: Secured Parking | B12: 41 | C12: 25 | D12: 25 | E12: 32 | F12: 30 | G12: 22 | H12: =SUM(B12:G12)
A13: Market Rent — Shop ($/SF) | B13: 18 | C13: 19 | D13: 18 | E13: 16 | F13: 19 | G13: 17 | H13: =SUM(B13:G13)
A14: Market Rent — Studio ($/SF) | B14: 16 | C14: 19 | D14: 18 | E14: 16 | F14: 19 | G14: 17 | H14: =SUM(B14:G14)
A15: 2025 Assessed Value | B15: 17500000 | C15: 13174536 | D15: 10800000 | E15: 6168340 | F15: 14500000 | G15: 8839548 | H15: =SUM(B15:G15)
A16: Millage Rate | B16: 0.02059675 | C16: 0.0167548 | D16: 0.01722747 | E16: 0.02345667 | F16: 0.02 | G16: 0.0159622
A17: Parcel | B17: Dallas CAD #140067300A01R0000 | C17: Collin CAD #2761885 | D17: Denton CAD #983656 | E17: Dallas CAD #380215100D0060000 | F17: ESTIMATED — confirm with seller | G17: Denton CAD #742232, #742233, #742235
A18: In-Place NOI (OM) | B18: 1581944 | C18: 1365615 | D18: 1189505 | E18: 455529 | F18: 1318936 | G18: 366683 | H18: =SUM(B18:G18)
A19: FY27 NOI (OM Proforma) | B19: 1723687 | C19: 1376978 | D19: 1187939 | E19: 682764 | F19: 1400000 | G19: 803301 | H19: =SUM(B19:G19)
A20: FY27 CAM | B20: 238800 | C20: 169748 | D20: 166856 | E20: 127914 | F20: 187130 | G20: 110358 | H20: =SUM(B20:G20)
A21: FY27 Utilities | B21: 118489 | C21: 81730 | D21: 91790 | E21: 46757 | F21: 90000 | G21: 103125 | H21: =SUM(B21:G21)
A22: FY27 Management Fee | B22: 105166 | C22: 80187 | D22: 70523 | E22: 43482 | F22: 88000 | G22: 50335 | H22: =SUM(B22:G22)
A23: FY27 Insurance | B23: 78963 | C23: 73087 | D23: 58043 | E23: 39986 | F23: 80650 | G23: 48744 | H23: =SUM(B23:G23)
A24: FY27 RE Taxes | B24: 364047 | C24: 222944 | D24: 187918 | E24: 146136 | F24: 290000 | G24: 142510 | H24: =SUM(B24:G24)
A25: FY27 Tenant Upgrade Rent | B25: 108444 | C25: 54160 | D25: 116942 | E25: 50992 | F25: 80000 | G25: 47411 | H25: =SUM(B25:G25)
A26: FY27 Parking Rent | B26: 89347 | C26: 32227 | D26: 26438 | E26: 5664 | F26: 35000 | G26: 15169 | H26: =SUM(B26:G26)

Sheet MLA
A1: MARKET LEASING ASSUMPTIONS
A2: Defaults to OM values. Edit per property/unit type to override global assumptions.
A4: Property / Unit Type | B4: Unit Type | C4: Market Rent ($/SF) | D4: Rent Growth | E4: In-Lease Escalator | F4: Lease Term (mo) | G4: TI New $/SF | H4: TI Renewal $/SF | I4: LC New % | J4: LC Renewal % | K4: Downtime New (mo) | L4: Retention %
A5: Carrollton — Shop | B5: Shop | C5: 18 | D5: =GrowthMarketRent | E5: =EscalatorInLease | F5: =LeaseTermMonths | G5: =TINew | H5: =TIRenewal | I5: =LCNew | J5: =LCRenewal | K5: =DowntimeNew | L5: =Retention
A6: Carrollton — Studio | B6: Studio | C6: 16 | D6: =GrowthMarketRent | E6: =EscalatorInLease | F6: =LeaseTermMonths | G6: =TINew | H6: =TIRenewal | I6: =LCNew | J6: =LCRenewal | K6: =DowntimeNew | L6: =Retention
A7: Frisco | B7: All | C7: 19 | D7: =GrowthMarketRent | E7: =EscalatorInLease | F7: =LeaseTermMonths | G7: =TINew | H7: =TIRenewal | I7: =LCNew | J7: =LCRenewal | K7: =DowntimeNew | L7: =Retention
A8: Lewisville | B8: All | C8: 18 | D8: =GrowthMarketRent | E8: =EscalatorInLease | F8: =LeaseTermMonths | G8: =TINew | H8: =TIRenewal | I8: =LCNew | J8: =LCRenewal | K8: =DowntimeNew | L8: =Retention
A9: Mesquite | B9: All | C9: 16 | D9: =GrowthMarketRent | E9: =EscalatorInLease | F9: =LeaseTermMonths | G9: =TINew | H9: =TIRenewal | I9: =LCNew | J9: =LCRenewal | K9: =DowntimeNew | L9: =Retention
A10: Plano | B10: All | C10: 19 | D10: =GrowthMarketRent | E10: =EscalatorInLease | F10: =LeaseTermMonths | G10: =TINew | H10: =TIRenewal | I10: =LCNew | J10: =LCRenewal | K10: =DowntimeNew | L10: =Retention
A11: Roanoke | B11: All | C11: 17 | D11: =GrowthMarketRent | E11: =EscalatorInLease | F11: =LeaseTermMonths | G11: =TINew | H11: =TIRenewal | I11: =LCNew | J11: =LCRenewal | K11: =DowntimeNew | L11: =Retention

Sheet Rent Roll
A1: RENT ROLL (162 tenant-suites) — FY27–FY37 dynamic base rent & capital
A2: Formulas apply Treatment flag (Market/Option/Vacate/LeaseUp) per tenant. Market Rent PSF (col H) is looked up from MLA tab. Edit Treatment col to switch scenarios.
A4: Property | B4: Suite | C4: Tenant | D4: SF | E4: Lease Start | F4: Lease End | G4: In-Place PSF | H4: Market PSF | I4: Treatment | J4: Unit Type | K4: Status | L4: Notes | M4: YrsAtStart | N4: BaseRent FY27 | O4: BaseRent FY28 | P4: BaseRent FY29 | Q4: BaseRent FY30 | R4: BaseRent FY31 | S4: BaseRent FY32 | T4: BaseRent FY33 | U4: BaseRent FY34 | V4: BaseRent FY35 | W4: BaseRent FY36 | X4: BaseRent FY37 | Y4: Capital FY27 | Z4: Capital FY28 | AA4: Capital FY29 | AB4: Capital FY30 | AC4: Capital FY31 | AD4: Capital FY32 | AE4: Capital FY33 | AF4: Capital FY34 | AG4: Capital FY35 | AH4: Capital FY36 | AI4: Capital FY37 | AJ4: Downtime FY27 | AK4: Downtime FY28 | AL4: Downtime FY29 | AM4: Downtime FY30 | AN4: Downtime FY31 | AO4: Downtime FY32 | AP4: Downtime FY33 | AQ4: Downtime FY34 | AR4: Downtime FY35 | AS4: Downtime FY36 | AT4: Downtime FY37
A5: Carrollton | B5: 100 | C5: Titan Glass LLC | D5: 2600 | E5: 45200 | F5: 46447 | G5: 14.971538 | H5: =VLOOKUP("Carrollton — "&J5,MLA!$A$5:$L$11,3,FALSE) | I5: Market | J5: Shop | K5: Occupied | L5: Shop; Guarantor: Adren Savitch | M5: =IF(E5="",0,(AnalysisStart-E5)/365.25) | N5: =IFERROR(IF(I5="LeaseUp",H5*D5*(1+GrowthMarketRent)^0*IF(0=0,(12-DowntimeNew)/12,1),IF(F5="",0,IF(F5>=DATE(2027+0,4,30),G5*D5*(1+EscalatorInLease)^(0+M5),IF(F5<DATE(2026+0,5,1),IF(I5="Vacate",H5*D5*(1+GrowthMarketRent)^0*IF(INT((DATE(2026+0,10,31)-F5)/365.25)=0,(12-DowntimeNew)/12,1),IF(I5="Option",G5*D5*1.025*(1+EscalatorInLease)^0,IF(I5="Market",Retention*G5*D5*(1+EscalatorInLease)^(0+M5)+(1-Retention)*H5*D5*(1+GrowthMarketRent)^0*IF(INT((DATE(2026+0,10,31)-F5)/365.25)=0,(12-DowntimeNew)/12,1),IF(I5="LeaseUp",H5*D5*(1+GrowthMarketRent)^0*IF(0=0,(12-DowntimeNew)/12,1),0)))),((F5-DATE(2026+0,5,1))/365.25)*G5*D5*(1+EscalatorInLease)^(0+M5)+((DATE(2027+0,4,30)-F5)/365.25)*IF(I5="Vacate",H5*D5*(1+GrowthMarketRent)^0*IF(INT((DATE(2026+0,10,31)-F5)/365.25)=0,(12-DowntimeNew)/12,1),IF(I5="Option",G5*D5*1.025*(1+EscalatorInLease)^0,IF(I5="Market",Retention*G5*D5*(1+EscalatorInLease)^(0+M5)+(1-Retention)*H5*D5*(1+GrowthMarketRent)^0*IF(INT((DATE(2026+0,10,31)-F5)/365.25)=0,(12-DowntimeNew)/12,1),IF(I5="LeaseUp",H5*D5*(1+GrowthMarketRent)^0*IF(0=0,(12-DowntimeNew)/12,1),0)))))))),0) | O5: =IFERROR(IF(I5="LeaseUp",H5*D5*(1+GrowthMarketRent)^1*IF(1=0,(12-DowntimeNew)/12,1),IF(F5="",0,IF(F5>=DATE(2027+1,4,30),G5*D5*(1+EscalatorInLease)^(1+M5),IF(F5<DATE(2026+1,5,1),IF(I5="Vacate",H5*D5*(1+GrowthMarketRent)^1*IF(INT((DATE(2026+1,10,31)-F5)/365.25)=0,(12-DowntimeNew)/12,1),IF(I5="Option",G5*D5*1.025*(1+EscalatorInLease)^1,IF(I5="Market",Retention*G5*D5*(1+EscalatorInLease)^(1+M5)+(1-Retention)*H5*D5*(1+GrowthMarketRent)^1*IF(INT((DATE(2026+1,10,31)-F5)/365.25)=0,(12-DowntimeNew)/12,1),IF(I5="LeaseUp",H5*D5*(1+GrowthMarketRent)^1*IF(1=0,(12-DowntimeNew)/12,1),0)))),((F5-DATE(2026+1,5,1))/365.25)*G5*D5*(1+EscalatorInLease)^(1+M5)+((DATE(2027+1,4,30)-F5)/365.25)*IF(I5="Vacate",H5*D5*(1+GrowthMarketRent)^1*IF(INT((DATE(2026+1,10,31)-F5)/365.25)=0,(12-DowntimeNew)/12,1),IF(I5="Option",G5*D5*1.025*(1+EscalatorInLease)^1,IF(I5="Market",Retention*G5*D5*(1+EscalatorInLease)^(1+M5)+(1-Retention)*H5*D5*(1+GrowthMarketRent)^1*IF(INT((DATE(2026+1,10,31)-F5)/365.25)=0,(12-DowntimeNew)/12,1),IF(I5="LeaseUp",H5*D5*(1+GrowthMarketRent)^1*IF(1=0,(12-DowntimeNew)/12,1),0)))))))),0) | P5: =IFERROR(IF(I5="LeaseUp",H5*D5*(1+GrowthMarketRent)^2*IF(2=0,(12-DowntimeNew)/12,1),IF(F5="",0,IF(F5>=DATE(2027+2,4,30),G5*D5*(1+EscalatorInLease)^(2+M5),IF(F5<DATE(2026+2,5,1),IF(I5="Vacate",H5*D5*(1+GrowthMarketRent)^2*IF(INT((DATE(2026+2,10,31)-F5)/365.25)=0,(12-DowntimeNew)/12,1),IF(I5="Option",G5*D5*1.025*(1+EscalatorInLease)^2,IF(I5="Market",Retention*G5*D5*(1+EscalatorInLease)^(2+M5)+(1-Retention)*H5*D5*(1+GrowthMarketRent)^2*IF(INT((DATE(2026+2,10,31)-F5)/365.25)=0,(12-DowntimeNew)/12,1),IF(I5="LeaseUp",H5*D5*(1+GrowthMarketRent)^2*IF(2=0,(12-DowntimeNew)/12,1),0)))),((F5-DATE(2026+2,5,1))/365.25)*G5*D5*(1+EscalatorInLease)^(2+M5)+((DATE(2027+2,4,30)-F5)/365.25)*IF(I5="Vacate",H5*D5*(1+GrowthMarketRent)^2*IF(INT((DATE(2026+2,10,31)-F5)/365.25)=0,(12-DowntimeNew)/12,1),IF(I5="Option",G5*D5*1.025*(1+EscalatorInLease)^2,IF(I5="Market",Retention*G5*D5*(1+EscalatorInLease)^(2+M5)+(1-Retention)*H5*D5*(1+GrowthMarketRent)^2*IF(INT((DATE(2026+2,10,31)-F5)/365.25)=0,(12-DowntimeNew)/12,1),IF(I5="LeaseUp",H5*D5*(1+GrowthMarketRent)^2*IF(2=0,(12-DowntimeNew)/12,1),0)))))))),0) | Q5: =IFERROR(IF(I5="LeaseUp",H5*D5*(1+GrowthMarketRent)^3*IF(3=0,(12-DowntimeNew)/12,1),IF(F5="",0,IF(F5>=DATE(2027+3,4,30),G5*D5*(1+EscalatorInLease)^(3+M5),IF(F5<DATE(2026+3,5,1),IF(I5="Vacate",H5*D5*(1+GrowthMarketRent)^3*IF(INT((DATE(2026+3,10,31)-F5)/365.25)=0,(12-DowntimeNew)/12,1),IF(I5="Option",G5*D5*1.025*(1+EscalatorInLease)^3,IF(I5="Market",Retention*G5*D5*(1+EscalatorInLease)^(3+M5)+(1-Retention)*H5*D5*(1+GrowthMarketRent)^3*IF(INT((DATE(2026+3,10,31)-F5)/365.25)=0,(12-DowntimeNew)/12,1),IF(I5="LeaseUp",H5*D5*(1+GrowthMarketRent)^3*IF(3=0,(12-DowntimeNew)/12,1),0)))),((F5-DATE(2026+3,5,1))/365.25)*G5*D5*(1+EscalatorInLease)^(3+M5)+((DATE(2027+3,4,30)-F5)/365.25)*IF(I5="Vacate",H5*D5*(1+GrowthMarketRent)^3*IF(INT((DATE(2026+3,10,31)-F5)/365.25)=0,(12-DowntimeNew)/12,1),IF(I5="Option",G5*D5*1.025*(1+EscalatorInLease)^3,IF(I5="Market",Retention*G5*D5*(1+EscalatorInLease)^(3+M5)+(1-Retention)*H5*D5*(1+GrowthMarketRent)^3*IF(INT((DATE(2026+3,10,31)-F5)/365.25)=0,(12-DowntimeNew)/12,1),IF(I5="LeaseUp",H5*D5*(1+GrowthMarketRent)^3*IF(3=0,(12-DowntimeNew)/12,1),0)))))))),0) | R5: =IFERROR(IF(I5="LeaseUp",H5*D5*(1+GrowthMarketRent)^4*IF(4=0,(12-DowntimeNew)/12,1),IF(F5="",0,IF(F5>=DATE(2027+4,4,30),G5*D5*(1+EscalatorInLease)^(4+M5),IF(F5<DATE(2026+4,5,1),IF(I5="Vacate",H5*D5*(1+GrowthMarketRent)^4*IF(INT((DATE(2026+4,10,31)-F5)/365.25)=0,(12-DowntimeNew)/12,1),IF(I5="Option",G5*D5*1.025*(1+EscalatorInLease)^4,IF(I5="Market",Retention*G5*D5*(1+EscalatorInLease)^(4+M5)+(1-Retention)*H5*D5*(1+GrowthMarketRent)^4*IF(INT((DATE(2026+4,10,31)-F5)/365.25)=0,(12-DowntimeNew)/12,1),IF(I5="LeaseUp",H5*D5*(1+GrowthMarketRent)^4*IF(4=0,(12-DowntimeNew)/12,1),0)))),((F5-DATE(2026+4,5,1))/365.25)*G5*D5*(1+EscalatorInLease)^(4+M5)+((DATE(2027+4,4,30)-F5)/365.25)*IF(I5="Vacate",H5*D5*(1+GrowthMarketRent)^4*IF(INT((DATE(2026+4,10,31)-F5)/365.25)=0,(12-DowntimeNew)/12,1),IF(I5="Option",G5*D5*1.025*(1+EscalatorInLease)^4,IF(I5="Market",Retention*G5*D5*(1+EscalatorInLease)^(4+M5)+(1-Retention)*H5*D5*(1+GrowthMarketRent)^4*IF(INT((DATE(2026+4,10,31)-F5)/365.25)=0,(12-DowntimeNew)/12,1),IF(I5="LeaseUp",H5*D5*(1+GrowthMarketRent)^4*IF(4=0,(12-DowntimeNew)/12,1),0)))))))),0) | S5: =IFERROR(IF(I5="LeaseUp",H5*D5*(1+GrowthMarketRent)^5*IF(5=0,(12-DowntimeNew)/12,1),IF(F5="",0,IF(F5>=DATE(2027+5,4,30),G5*D5*(1+EscalatorInLease)^(5+M5),IF(F5<DATE(2026+5,5,1),IF(I5="Vacate",H5*D5*(1+GrowthMarketRent)^5*IF(INT((DATE(2026+5,10,31)-F5)/365.25)=0,(12-DowntimeNew)/12,1),IF(I5="Option",G5*D5*1.025*(1+EscalatorInLease)^5,IF(I5="Market",Retention*G5*D5*(1+EscalatorInLease)^(5+M5)+(1-Retention)*H5*D5*(1+GrowthMarketRent)^5*IF(INT((DATE(2026+5,10,31)-F5)/365.25)=0,(12-DowntimeNew)/12,1),IF(I5="LeaseUp",H5*D5*(1+GrowthMarketRent)^5*IF(5=0,(12-DowntimeNew)/12,1),0)))),((F5-DATE(2026+5,5,1))/365.25)*G5*D5*(1+EscalatorInLease)^(5+M5)+((DATE(2027+5,4,30)-F5)/365.25)*IF(I5="Vacate",H5*D5*(1+GrowthMarketRent)^5*IF(INT((DATE(2026+5,10,31)-F5)/365.25)=0,(12-DowntimeNew)/12,1),IF(I5="Option",G5*D5*1.025*(1+EscalatorInLease)^5,IF(I5="Market",Retention*G5*D5*(1+EscalatorInLease)^(5+M5)+(1-Retention)*H5*D5*(1+GrowthMarketRent)^5*IF(INT((DATE(2026+5,10,31)-F5)/365.25)=0,(12-DowntimeNew)/12,1),IF(I5="LeaseUp",H5*D5*(1+GrowthMarketRent)^5*IF(5=0,(12-DowntimeNew)/12,1),0)))))))),0) | T5: =IFERROR(IF(I5="LeaseUp",H5*D5*(1+GrowthMarketRent)^6*IF(6=0,(12-DowntimeNew)/12,1),IF(F5="",0,IF(F5>=DATE(2027+6,4,30),G5*D5*(1+EscalatorInLease)^(6+M5),IF(F5<DATE(2026+6,5,1),IF(I5="Vacate",H5*D5*(1+GrowthMarketRent)^6*IF(INT((DATE(2026+6,10,31)-F5)/365.25)=0,(12-DowntimeNew)/12,1),IF(I5="Option",G5*D5*1.025*(1+EscalatorInLease)^6,IF(I5="Market",Retention*G5*D5*(1+EscalatorInLease)^(6+M5)+(1-Retention)*H5*D5*(1+GrowthMarketRent)^6*IF(INT((DATE(2026+6,10,31)-F5)/365.25)=0,(12-DowntimeNew)/12,1),IF(I5="LeaseUp",H5*D5*(1+GrowthMarketRent)^6*IF(6=0,(12-DowntimeNew)/12,1),0)))),((F5-DATE(2026+6,5,1))/365.25)*G5*D5*(1+EscalatorInLease)^(6+M5)+((DATE(2027+6,4,30)-F5)/365.25)*IF(I5="Vacate",H5*D5*(1+GrowthMarketRent)^6*IF(INT((DATE(2026+6,10,31)-F5)/365.25)=0,(12-DowntimeNew)/12,1),IF(I5="Option",G5*D5*1.025*(1+EscalatorInLease)^6,IF(I5="Market",Retention*G5*D5*(1+EscalatorInLease)^(6+M5)+(1-Retention)*H5*D5*(1+GrowthMarketRent)^6*IF(INT((DATE(2026+6,10,31)-F5)/365.25)=0,(12-DowntimeNew)/12,1),IF(I5="LeaseUp",H5*D5*(1+GrowthMarketRent)^6*IF(6=0,(12-DowntimeNew)/12,1),0)))))))),0) | U5: =IFERROR(IF(I5="LeaseUp",H5*D5*(1+GrowthMarketRent)^7*IF(7=0,(12-DowntimeNew)/12,1),IF(F5="",0,IF(F5>=DATE(2027+7,4,30),G5*D5*(1+EscalatorInLease)^(7+M5),IF(F5<DATE(2026+7,5,1),IF(I5="Vacate",H5*D5*(1+GrowthMarketRent)^7*IF(INT((DATE(2026+7,10,31)-F5)/365.25)=0,(12-DowntimeNew)/12,1),IF(I5="Option",G5*D5*1.025*(1+EscalatorInLease)^7,IF(I5="Market",Retention*G5*D5*(1+EscalatorInLease)^(7+M5)+(1-Retention)*H5*D5*(1+GrowthMarketRent)^7*IF(INT((DATE(2026+7,10,31)-F5)/365.25)=0,(12-DowntimeNew)/12,1),IF(I5="LeaseUp",H5*D5*(1+GrowthMarketRent)^7*IF(7=0,(12-DowntimeNew)/12,1),0)))),((F5-DATE(2026+7,5,1))/365.25)*G5*D5*(1+EscalatorInLease)^(7+M5)+((DATE(2027+7,4,30)-F5)/365.25)*IF(I5="Vacate",H5*D5*(1+GrowthMarketRent)^7*IF(INT((DATE(2026+7,10,31)-F5)/365.25)=0,(12-DowntimeNew)/12,1),IF(I5="Option",G5*D5*1.025*(1+EscalatorInLease)^7,IF(I5="Market",Retention*G5*D5*(1+EscalatorInLease)^(7+M5)+(1-Retention)*H5*D5*(1+GrowthMarketRent)^7*IF(INT((DATE(2026+7,10,31)-F5)/365.25)=0,(12-DowntimeNew)/12,1),IF(I5="LeaseUp",H5*D5*(1+GrowthMarketRent)^7*IF(7=0,(12-DowntimeNew)/12,1),0)))))))),0) | V5: =IFERROR(IF(I5="LeaseUp",H5*D5*(1+GrowthMarketRent)^8*IF(8=0,(12-DowntimeNew)/12,1),IF(F5="",0,IF(F5>=DATE(2027+8,4,30),G5*D5*(1+EscalatorInLease)^(8+M5),IF(F5<DATE(2026+8,5,1),IF(I5="Vacate",H5*D5*(1+GrowthMarketRent)^8*IF(INT((DATE(2026+8,10,31)-F5)/365.25)=0,(12-DowntimeNew)/12,1),IF(I5="Option",G5*D5*1.025*(1+EscalatorInLease)^8,IF(I5="Market",Retention*G5*D5*(1+EscalatorInLease)^(8+M5)+(1-Retention)*H5*D5*(1+GrowthMarketRent)^8*IF(INT((DATE(2026+8,10,31)-F5)/365.25)=0,(12-DowntimeNew)/12,1),IF(I5="LeaseUp",H5*D5*(1+GrowthMarketRent)^8*IF(8=0,(12-DowntimeNew)/12,1),0)))),((F5-DATE(2026+8,5,1))/365.25)*G5*D5*(1+EscalatorInLease)^(8+M5)+((DATE(2027+8,4,30)-F5)/365.25)*IF(I5="Vacate",H5*D5*(1+GrowthMarketRent)^8*IF(INT((DATE(2026+8,10,31)-F5)/365.25)=0,(12-DowntimeNew)/12,1),IF(I5="Option",G5*D5*1.025*(1+EscalatorInLease)^8,IF(I5="Market",Retention*G5*D5*(1+EscalatorInLease)^(8+M5)+(1-Retention)*H5*D5*(1+GrowthMarketRent)^8*IF(INT((DATE(2026+8,10,31)-F5)/365.25)=0,(12-DowntimeNew)/12,1),IF(I5="LeaseUp",H5*D5*(1+GrowthMarketRent)^8*IF(8=0,(12-DowntimeNew)/12,1),0)))))))),0) | W5: =IFERROR(IF(I5="LeaseUp",H5*D5*(1+GrowthMarketRent)^9*IF(9=0,(12-DowntimeNew)/12,1),IF(F5="",0,IF(F5>=DATE(2027+9,4,30),G5*D5*(1+EscalatorInLease)^(9+M5),IF(F5<DATE(2026+9,5,1),IF(I5="Vacate",H5*D5*(1+GrowthMarketRent)^9*IF(INT((DATE(2026+9,10,31)-F5)/365.25)=0,(12-DowntimeNew)/12,1),IF(I5="Option",G5*D5*1.025*(1+EscalatorInLease)^9,IF(I5="Market",Retention*G5*D5*(1+EscalatorInLease)^(9+M5)+(1-Retention)*H5*D5*(1+GrowthMarketRent)^9*IF(INT((DATE(2026+9,10,31)-F5)/365.25)=0,(12-DowntimeNew)/12,1),IF(I5="LeaseUp",H5*D5*(1+GrowthMarketRent)^9*IF(9=0,(12-DowntimeNew)/12,1),0)))),((F5-DATE(2026+9,5,1))/365.25)*G5*D5*(1+EscalatorInLease)^(9+M5)+((DATE(2027+9,4,30)-F5)/365.25)*IF(I5="Vacate",H5*D5*(1+GrowthMarketRent)^9*IF(INT((DATE(2026+9,10,31)-F5)/365.25)=0,(12-DowntimeNew)/12,1),IF(I5="Option",G5*D5*1.025*(1+EscalatorInLease)^9,IF(I5="Market",Retention*G5*D5*(1+EscalatorInLease)^(9+M5)+(1-Retention)*H5*D5*(1+GrowthMarketRent)^9*IF(INT((DATE(2026+9,10,31)-F5)/365.25)=0,(12-DowntimeNew)/12,1),IF(I5="LeaseUp",H5*D5*(1+GrowthMarketRent)^9*IF(9=0,(12-DowntimeNew)/12,1),0)))))))),0) | X5: =IFERROR(IF(I5="LeaseUp",H5*D5*(1+GrowthMarketRent)^10*IF(10=0,(12-DowntimeNew)/12,1),IF(F5="",0,IF(F5>=DATE(2027+10,4,30),G5*D5*(1+EscalatorInLease)^(10+M5),IF(F5<DATE(2026+10,5,1),IF(I5="Vacate",H5*D5*(1+GrowthMarketRent)^10*IF(INT((DATE(2026+10,10,31)-F5)/365.25)=0,(12-DowntimeNew)/12,1),IF(I5="Option",G5*D5*1.025*(1+EscalatorInLease)^10,IF(I5="Market",Retention*G5*D5*(1+EscalatorInLease)^(10+M5)+(1-Retention)*H5*D5*(1+GrowthMarketRent)^10*IF(INT((DATE(2026+10,10,31)-F5)/365.25)=0,(12-DowntimeNew)/12,1),IF(I5="LeaseUp",H5*D5*(1+GrowthMarketRent)^10*IF(10=0,(12-DowntimeNew)/12,1),0)))),((F5-DATE(2026+10,5,1))/365.25)*G5*D5*(1+EscalatorInLease)^(10+M5)+((DATE(2027+10,4,30)-F5)/365.25)*IF(I5="Vacate",H5*D5*(1+GrowthMarketRent)^10*IF(INT((DATE(2026+10,10,31)-F5)/365.25)=0,(12-DowntimeNew)/12,1),IF(I5="Option",G5*D5*1.025*(1+EscalatorInLease)^10,IF(I5="Market",Retention*G5*D5*(1+EscalatorInLease)^(10+M5)+(1-Retention)*H5*D5*(1+GrowthMarketRent)^10*IF(INT((DATE(2026+10,10,31)-F5)/365.25)=0,(12-DowntimeNew)/12,1),IF(I5="LeaseUp",H5*D5*(1+GrowthMarketRent)^10*IF(10=0,(12-DowntimeNew)/12,1),0)))))))),0) | Y5: =IFERROR(IF(AND(I5="LeaseUp",0=0),(IF(I5="Vacate",TINew*D5,IF(I5="Market",Retention*TIRenewal*D5+(1-Retention)*TINew*D5,IF(I5="LeaseUp",TINew*D5,IF(I5="Option",TIRenewal*D5,0)))))+(IF(I5="Vacate",LCNew*H5*D5*(1+GrowthMarketRent)^0,IF(I5="Market",Retention*LCRenewal*H5*D5*(1+GrowthMarketRent)^0+(1-Retention)*LCNew*H5*D5*(1+GrowthMarketRent)^0,IF(I5="LeaseUp",LCNew*H5*D5*(1+GrowthMarketRent)^0,IF(I5="Option",LCRenewal*H5*D5*(1+GrowthMarketRent)^0,0))))),IF(F5="",0,IF(AND(F5>=DATE(2026+0,5,1),F5<=DATE(2027+0,4,30)),(IF(I5="Vacate",TINew*D5,IF(I5="Market",Retention*TIRenewal*D5+(1-Retention)*TINew*D5,IF(I5="LeaseUp",TINew*D5,IF(I5="Option",TIRenewal*D5,0)))))+(IF(I5="Vacate",LCNew*H5*D5*(1+GrowthMarketRent)^0,IF(I5="Market",Retention*LCRenewal*H5*D5*(1+GrowthMarketRent)^0+(1-Retention)*LCNew*H5*D5*(1+GrowthMarketRent)^0,IF(I5="LeaseUp",LCNew*H5*D5*(1+GrowthMarketRent)^0,IF(I5="Option",LCRenewal*H5*D5*(1+GrowthMarketRent)^0,0))))),0))),0) | Z5: =IFERROR(IF(AND(I5="LeaseUp",1=0),(IF(I5="Vacate",TINew*D5,IF(I5="Market",Retention*TIRenewal*D5+(1-Retention)*TINew*D5,IF(I5="LeaseUp",TINew*D5,IF(I5="Option",TIRenewal*D5,0)))))+(IF(I5="Vacate",LCNew*H5*D5*(1+GrowthMarketRent)^1,IF(I5="Market",Retention*LCRenewal*H5*D5*(1+GrowthMarketRent)^1+(1-Retention)*LCNew*H5*D5*(1+GrowthMarketRent)^1,IF(I5="LeaseUp",LCNew*H5*D5*(1+GrowthMarketRent)^1,IF(I5="Option",LCRenewal*H5*D5*(1+GrowthMarketRent)^1,0))))),IF(F5="",0,IF(AND(F5>=DATE(2026+1,5,1),F5<=DATE(2027+1,4,30)),(IF(I5="Vacate",TINew*D5,IF(I5="Market",Retention*TIRenewal*D5+(1-Retention)*TINew*D5,IF(I5="LeaseUp",TINew*D5,IF(I5="Option",TIRenewal*D5,0)))))+(IF(I5="Vacate",LCNew*H5*D5*(1+GrowthMarketRent)^1,IF(I5="Market",Retention*LCRenewal*H5*D5*(1+GrowthMarketRent)^1+(1-Retention)*LCNew*H5*D5*(1+GrowthMarketRent)^1,IF(I5="LeaseUp",LCNew*H5*D5*(1+GrowthMarketRent)^1,IF(I5="Option",LCRenewal*H5*D5*(1+GrowthMarketRent)^1,0))))),0))),0) | AA5: =IFERROR(IF(AND(I5="LeaseUp",2=0),(IF(I5="Vacate",TINew*D5,IF(I5="Market",Retention*TIRenewal*D5+(1-Retention)*TINew*D5,IF(I5="LeaseUp",TINew*D5,IF(I5="Option",TIRenewal*D5,0)))))+(IF(I5="Vacate",LCNew*H5*D5*(1+GrowthMarketRent)^2,IF(I5="Market",Retention*LCRenewal*H5*D5*(1+GrowthMarketRent)^2+(1-Retention)*LCNew*H5*D5*(1+GrowthMarketRent)^2,IF(I5="LeaseUp",LCNew*H5*D5*(1+GrowthMarketRent)^2,IF(I5="Option",LCRenewal*H5*D5*(1+GrowthMarketRent)^2,0))))),IF(F5="",0,IF(AND(F5>=DATE(2026+2,5,1),F5<=DATE(2027+2,4,30)),(IF(I5="Vacate",TINew*D5,IF(I5="Market",Retention*TIRenewal*D5+(1-Retention)*TINew*D5,IF(I5="LeaseUp",TINew*D5,IF(I5="Option",TIRenewal*D5,0)))))+(IF(I5="Vacate",LCNew*H5*D5*(1+GrowthMarketRent)^2,IF(I5="Market",Retention*LCRenewal*H5*D5*(1+GrowthMarketRent)^2+(1-Retention)*LCNew*H5*D5*(1+GrowthMarketRent)^2,IF(I5="LeaseUp",LCNew*H5*D5*(1+GrowthMarketRent)^2,IF(I5="Option",LCRenewal*H5*D5*(1+GrowthMarketRent)^2,0))))),0))),0) | AB5: =IFERROR(IF(AND(I5="LeaseUp",3=0),(IF(I5="Vacate",TINew*D5,IF(I5="Market",Retention*TIRenewal*D5+(1-Retention)*TINew*D5,IF(I5="LeaseUp",TINew*D5,IF(I5="Option",TIRenewal*D5,0)))))+(IF(I5="Vacate",LCNew*H5*D5*(1+GrowthMarketRent)^3,IF(I5="Market",Retention*LCRenewal*H5*D5*(1+GrowthMarketRent)^3+(1-Retention)*LCNew*H5*D5*(1+GrowthMarketRent)^3,IF(I5="LeaseUp",LCNew*H5*D5*(1+GrowthMarketRent)^3,IF(I5="Option",LCRenewal*H5*D5*(1+GrowthMarketRent)^3,0))))),IF(F5="",0,IF(AND(F5>=DATE(2026+3,5,1),F5<=DATE(2027+3,4,30)),(IF(I5="Vacate",TINew*D5,IF(I5="Market",Retention*TIRenewal*D5+(1-Retention)*TINew*D5,IF(I5="LeaseUp",TINew*D5,IF(I5="Option",TIRenewal*D5,0)))))+(IF(I5="Vacate",LCNew*H5*D5*(1+GrowthMarketRent)^3,IF(I5="Market",Retention*LCRenewal*H5*D5*(1+GrowthMarketRent)^3+(1-Retention)*LCNew*H5*D5*(1+GrowthMarketRent)^3,IF(I5="LeaseUp",LCNew*H5*D5*(1+GrowthMarketRent)^3,IF(I5="Option",LCRenewal*H5*D5*(1+GrowthMarketRent)^3,0))))),0))),0) | AC5: =IFERROR(IF(AND(I5="LeaseUp",4=0),(IF(I5="Vacate",TINew*D5,IF(I5="Market",Retention*TIRenewal*D5+(1-Retention)*TINew*D5,IF(I5="LeaseUp",TINew*D5,IF(I5="Option",TIRenewal*D5,0)))))+(IF(I5="Vacate",LCNew*H5*D5*(1+GrowthMarketRent)^4,IF(I5="Market",Retention*LCRenewal*H5*D5*(1+GrowthMarketRent)^4+(1-Retention)*LCNew*H5*D5*(1+GrowthMarketRent)^4,IF(I5="LeaseUp",LCNew*H5*D5*(1+GrowthMarketRent)^4,IF(I5="Option",LCRenewal*H5*D5*(1+GrowthMarketRent)^4,0))))),IF(F5="",0,IF(AND(F5>=DATE(2026+4,5,1),F5<=DATE(2027+4,4,30)),(IF(I5="Vacate",TINew*D5,IF(I5="Market",Retention*TIRenewal*D5+(1-Retention)*TINew*D5,IF(I5="LeaseUp",TINew*D5,IF(I5="Option",TIRenewal*D5,0)))))+(IF(I5="Vacate",LCNew*H5*D5*(1+GrowthMarketRent)^4,IF(I5="Market",Retention*LCRenewal*H5*D5*(1+GrowthMarketRent)^4+(1-Retention)*LCNew*H5*D5*(1+GrowthMarketRent)^4,IF(I5="LeaseUp",LCNew*H5*D5*(1+GrowthMarketRent)^4,IF(I5="Option",LCRenewal*H5*D5*(1+GrowthMarketRent)^4,0))))),0))),0) | AD5: =IFERROR(IF(AND(I5="LeaseUp",5=0),(IF(I5="Vacate",TINew*D5,IF(I5="Market",Retention*TIRenewal*D5+(1-Retention)*TINew*D5,IF(I5="LeaseUp",TINew*D5,IF(I5="Option",TIRenewal*D5,0)))))+(IF(I5="Vacate",LCNew*H5*D5*(1+GrowthMarketRent)^5,IF(I5="Market",Retention*LCRenewal*H5*D5*(1+GrowthMarketRent)^5+(1-Retention)*LCNew*H5*D5*(1+GrowthMarketRent)^5,IF(I5="LeaseUp",LCNew*H5*D5*(1+GrowthMarketRent)^5,IF(I5="Option",LCRenewal*H5*D5*(1+GrowthMarketRent)^5,0))))),IF(F5="",0,IF(AND(F5>=DATE(2026+5,5,1),F5<=DATE(2027+5,4,30)),(IF(I5="Vacate",TINew*D5,IF(I5="Market",Retention*TIRenewal*D5+(1-Retention)*TINew*D5,IF(I5="LeaseUp",TINew*D5,IF(I5="Option",TIRenewal*D5,0)))))+(IF(I5="Vacate",LCNew*H5*D5*(1+GrowthMarketRent)^5,IF(I5="Market",Retention*LCRenewal*H5*D5*(1+GrowthMarketRent)^5+(1-Retention)*LCNew*H5*D5*(1+GrowthMarketRent)^5,IF(I5="LeaseUp",LCNew*H5*D5*(1+GrowthMarketRent)^5,IF(I5="Option",LCRenewal*H5*D5*(1+GrowthMarketRent)^5,0))))),0))),0) | AE5: =IFERROR(IF(AND(I5="LeaseUp",6=0),(IF(I5="Vacate",TINew*D5,IF(I5="Market",Retention*TIRenewal*D5+(1-Retention)*TINew*D5,IF(I5="LeaseUp",TINew*D5,IF(I5="Option",TIRenewal*D5,0)))))+(IF(I5="Vacate",LCNew*H5*D5*(1+GrowthMarketRent)^6,IF(I5="Market",Retention*LCRenewal*H5*D5*(1+GrowthMarketRent)^6+(1-Retention)*LCNew*H5*D5*(1+GrowthMarketRent)^6,IF(I5="LeaseUp",LCNew*H5*D5*(1+GrowthMarketRent)^6,IF(I5="Option",LCRenewal*H5*D5*(1+GrowthMarketRent)^6,0))))),IF(F5="",0,IF(AND(F5>=DATE(2026+6,5,1),F5<=DATE(2027+6,4,30)),(IF(I5="Vacate",TINew*D5,IF(I5="Market",Retention*TIRenewal*D5+(1-Retention)*TINew*D5,IF(I5="LeaseUp",TINew*D5,IF(I5="Option",TIRenewal*D5,0)))))+(IF(I5="Vacate",LCNew*H5*D5*(1+GrowthMarketRent)^6,IF(I5="Market",Retention*LCRenewal*H5*D5*(1+GrowthMarketRent)^6+(1-Retention)*LCNew*H5*D5*(1+GrowthMarketRent)^6,IF(I5="LeaseUp",LCNew*H5*D5*(1+GrowthMarketRent)^6,IF(I5="Option",LCRenewal*H5*D5*(1+GrowthMarketRent)^6,0))))),0))),0) | AF5: =IFERROR(IF(AND(I5="LeaseUp",7=0),(IF(I5="Vacate",TINew*D5,IF(I5="Market",Retention*TIRenewal*D5+(1-Retention)*TINew*D5,IF(I5="LeaseUp",TINew*D5,IF(I5="Option",TIRenewal*D5,0)))))+(IF(I5="Vacate",LCNew*H5*D5*(1+GrowthMarketRent)^7,IF(I5="Market",Retention*LCRenewal*H5*D5*(1+GrowthMarketRent)^7+(1-Retention)*LCNew*H5*D5*(1+GrowthMarketRent)^7,IF(I5="LeaseUp",LCNew*H5*D5*(1+GrowthMarketRent)^7,IF(I5="Option",LCRenewal*H5*D5*(1+GrowthMarketRent)^7,0))))),IF(F5="",0,IF(AND(F5>=DATE(2026+7,5,1),F5<=DATE(2027+7,4,30)),(IF(I5="Vacate",TINew*D5,IF(I5="Market",Retention*TIRenewal*D5+(1-Retention)*TINew*D5,IF(I5="LeaseUp",TINew*D5,IF(I5="Option",TIRenewal*D5,0)))))+(IF(I5="Vacate",LCNew*H5*D5*(1+GrowthMarketRent)^7,IF(I5="Market",Retention*LCRenewal*H5*D5*(1+GrowthMarketRent)^7+(1-Retention)*LCNew*H5*D5*(1+GrowthMarketRent)^7,IF(I5="LeaseUp",LCNew*H5*D5*(1+GrowthMarketRent)^7,IF(I5="Option",LCRenewal*H5*D5*(1+GrowthMarketRent)^7,0))))),0))),0) | AG5: =IFERROR(IF(AND(I5="LeaseUp",8=0),(IF(I5="Vacate",TINew*D5,IF(I5="Market",Retention*TIRenewal*D5+(1-Retention)*TINew*D5,IF(I5="LeaseUp",TINew*D5,IF(I5="Option",TIRenewal*D5,0)))))+(IF(I5="Vacate",LCNew*H5*D5*(1+GrowthMarketRent)^8,IF(I5="Market",Retention*LCRenewal*H5*D5*(1+GrowthMarketRent)^8+(1-Retention)*LCNew*H5*D5*(1+GrowthMarketRent)^8,IF(I5="LeaseUp",LCNew*H5*D5*(1+GrowthMarketRent)^8,IF(I5="Option",LCRenewal*H5*D5*(1+GrowthMarketRent)^8,0))))),IF(F5="",0,IF(AND(F5>=DATE(2026+8,5,1),F5<=DATE(2027+8,4,30)),(IF(I5="Vacate",TINew*D5,IF(I5="Market",Retention*TIRenewal*D5+(1-Retention)*TINew*D5,IF(I5="LeaseUp",TINew*D5,IF(I5="Option",TIRenewal*D5,0)))))+(IF(I5="Vacate",LCNew*H5*D5*(1+GrowthMarketRent)^8,IF(I5="Market",Retention*LCRenewal*H5*D5*(1+GrowthMarketRent)^8+(1-Retention)*LCNew*H5*D5*(1+GrowthMarketRent)^8,IF(I5="LeaseUp",LCNew*H5*D5*(1+GrowthMarketRent)^8,IF(I5="Option",LCRenewal*H5*D5*(1+GrowthMarketRent)^8,0))))),0))),0) | AH5: =IFERROR(IF(AND(I5="LeaseUp",9=0),(IF(I5="Vacate",TINew*D5,IF(I5="Market",Retention*TIRenewal*D5+(1-Retention)*TINew*D5,IF(I5="LeaseUp",TINew*D5,IF(I5="Option",TIRenewal*D5,0)))))+(IF(I5="Vacate",LCNew*H5*D5*(1+GrowthMarketRent)^9,IF(I5="Market",Retention*LCRenewal*H5*D5*(1+GrowthMarketRent)^9+(1-Retention)*LCNew*H5*D5*(1+GrowthMarketRent)^9,IF(I5="LeaseUp",LCNew*H5*D5*(1+GrowthMarketRent)^9,IF(I5="Option",LCRenewal*H5*D5*(1+GrowthMarketRent)^9,0))))),IF(F5="",0,IF(AND(F5>=DATE(2026+9,5,1),F5<=DATE(2027+9,4,30)),(IF(I5="Vacate",TINew*D5,IF(I5="Market",Retention*TIRenewal*D5+(1-Retention)*TINew*D5,IF(I5="LeaseUp",TINew*D5,IF(I5="Option",TIRenewal*D5,0)))))+(IF(I5="Vacate",LCNew*H5*D5*(1+GrowthMarketRent)^9,IF(I5="Market",Retention*LCRenewal*H5*D5*(1+GrowthMarketRent)^9+(1-Retention)*LCNew*H5*D5*(1+GrowthMarketRent)^9,IF(I5="LeaseUp",LCNew*H5*D5*(1+GrowthMarketRent)^9,IF(I5="Option",LCRenewal*H5*D5*(1+GrowthMarketRent)^9,0))))),0))),0) | AI5: =IFERROR(IF(AND(I5="LeaseUp",10=0),(IF(I5="Vacate",TINew*D5,IF(I5="Market",Retention*TIRenewal*D5+(1-Retention)*TINew*D5,IF(I5="LeaseUp",TINew*D5,IF(I5="Option",TIRenewal*D5,0)))))+(IF(I5="Vacate",LCNew*H5*D5*(1+GrowthMarketRent)^10,IF(I5="Market",Retention*LCRenewal*H5*D5*(1+GrowthMarketRent)^10+(1-Retention)*LCNew*H5*D5*(1+GrowthMarketRent)^10,IF(I5="LeaseUp",LCNew*H5*D5*(1+GrowthMarketRent)^10,IF(I5="Option",LCRenewal*H5*D5*(1+GrowthMarketRent)^10,0))))),IF(F5="",0,IF(AND(F5>=DATE(2026+10,5,1),F5<=DATE(2027+10,4,30)),(IF(I5="Vacate",TINew*D5,IF(I5="Market",Retention*TIRenewal*D5+(1-Retention)*TINew*D5,IF(I5="LeaseUp",TINew*D5,IF(I5="Option",TIRenewal*D5,0)))))+(IF(I5="Vacate",LCNew*H5*D5*(1+GrowthMarketRent)^10,IF(I5="Market",Retention*LCRenewal*H5*D5*(1+GrowthMarketRent)^10+(1-Retention)*LCNew*H5*D5*(1+GrowthMarketRent)^10,IF(I5="LeaseUp",LCNew*H5*D5*(1+GrowthMarketRent)^10,IF(I5="Option",LCRenewal*H5*D5*(1+GrowthMarketRent)^10,0))))),0))),0)
A6: Carrollton | B6: 104 | C6: Fluonics Inc. | D6: 2600 | E6: 45566 | F6: 46813 | G6: 16.4 | H6: =VLOOKUP("Carrollton — "&J6,MLA!$A$5:$L$11,3,FALSE) | I6: Market | J6: Shop | K6: Occupied | L6: Shop; Guarantor: Fluonics Co. Ltd (Korea) | M6: =IF(E6="",0,(AnalysisStart-E6)/365.25) | N6: =IFERROR(IF(I6="LeaseUp",H6*D6*(1+GrowthMarketRent)^0*IF(0=0,(12-DowntimeNew)/12,1),IF(F6="",0,IF(F6>=DATE(2027+0,4,30),G6*D6*(1+EscalatorInLease)^(0+M6),IF(F6<DATE(2026+0,5,1),IF(I6="Vacate",H6*D6*(1+GrowthMarketRent)^0*IF(INT((DATE(2026+0,10,31)-F6)/365.25)=0,(12-DowntimeNew)/12,1),IF(I6="Option",G6*D6*1.025*(1+EscalatorInLease)^0,IF(I6="Market",Retention*G6*D6*(1+EscalatorInLease)^(0+M6)+(1-Retention)*H6*D6*(1+GrowthMarketRent)^0*IF(INT((DATE(2026+0,10,31)-F6)/365.25)=0,(12-DowntimeNew)/12,1),IF(I6="LeaseUp",H6*D6*(1+GrowthMarketRent)^0*IF(0=0,(12-DowntimeNew)/12,1),0)))),((F6-DATE(2026+0,5,1))/365.25)*G6*D6*(1+EscalatorInLease)^(0+M6)+((DATE(2027+0,4,30)-F6)/365.25)*IF(I6="Vacate",H6*D6*(1+GrowthMarketRent)^0*IF(INT((DATE(2026+0,10,31)-F6)/365.25)=0,(12-DowntimeNew)/12,1),IF(I6="Option",G6*D6*1.025*(1+EscalatorInLease)^0,IF(I6="Market",Retention*G6*D6*(1+EscalatorInLease)^(0+M6)+(1-Retention)*H6*D6*(1+GrowthMarketRent)^0*IF(INT((DATE(2026+0,10,31)-F6)/365.25)=0,(12-DowntimeNew)/12,1),IF(I6="LeaseUp",H6*D6*(1+GrowthMarketRent)^0*IF(0=0,(12-DowntimeNew)/12,1),0)))))))),0) | O6: =IFERROR(IF(I6="LeaseUp",H6*D6*(1+GrowthMarketRent)^1*IF(1=0,(12-DowntimeNew)/12,1),IF(F6="",0,IF(F6>=DATE(2027+1,4,30),G6*D6*(1+EscalatorInLease)^(1+M6),IF(F6<DATE(2026+1,5,1),IF(I6="Vacate",H6*D6*(1+GrowthMarketRent)^1*IF(INT((DATE(2026+1,10,31)-F6)/365.25)=0,(12-DowntimeNew)/12,1),IF(I6="Option",G6*D6*1.025*(1+EscalatorInLease)^1,IF(I6="Market",Retention*G6*D6*(1+EscalatorInLease)^(1+M6)+(1-Retention)*H6*D6*(1+GrowthMarketRent)^1*IF(INT((DATE(2026+1,10,31)-F6)/365.25)=0,(12-DowntimeNew)/12,1),IF(I6="LeaseUp",H6*D6*(1+GrowthMarketRent)^1*IF(1=0,(12-DowntimeNew)/12,1),0)))),((F6-DATE(2026+1,5,1))/365.25)*G6*D6*(1+EscalatorInLease)^(1+M6)+((DATE(2027+1,4,30)-F6)/365.25)*IF(I6="Vacate",H6*D6*(1+GrowthMarketRent)^1*IF(INT((DATE(2026+1,10,31)-F6)/365.25)=0,(12-DowntimeNew)/12,1),IF(I6="Option",G6*D6*1.025*(1+EscalatorInLease)^1,IF(I6="Market",Retention*G6*D6*(1+EscalatorInLease)^(1+M6)+(1-Retention)*H6*D6*(1+GrowthMarketRent)^1*IF(INT((DATE(2026+1,10,31)-F6)/365.25)=0,(12-DowntimeNew)/12,1),IF(I6="LeaseUp",H6*D6*(1+GrowthMarketRent)^1*IF(1=0,(12-DowntimeNew)/12,1),0)))))))),0) | P6: =IFERROR(IF(I6="LeaseUp",H6*D6*(1+GrowthMarketRent)^2*IF(2=0,(12-DowntimeNew)/12,1),IF(F6="",0,IF(F6>=DATE(2027+2,4,30),G6*D6*(1+EscalatorInLease)^(2+M6),IF(F6<DATE(2026+2,5,1),IF(I6="Vacate",H6*D6*(1+GrowthMarketRent)^2*IF(INT((DATE(2026+2,10,31)-F6)/365.25)=0,(12-DowntimeNew)/12,1),IF(I6="Option",G6*D6*1.025*(1+EscalatorInLease)^2,IF(I6="Market",Retention*G6*D6*(1+EscalatorInLease)^(2+M6)+(1-Retention)*H6*D6*(1+GrowthMarketRent)^2*IF(INT((DATE(2026+2,10,31)-F6)/365.25)=0,(12-DowntimeNew)/12,1),IF(I6="LeaseUp",H6*D6*(1+GrowthMarketRent)^2*IF(2=0,(12-DowntimeNew)/12,1),0)))),((F6-DATE(2026+2,5,1))/365.25)*G6*D6*(1+EscalatorInLease)^(2+M6)+((DATE(2027+2,4,30)-F6)/365.25)*IF(I6="Vacate",H6*D6*(1+GrowthMarketRent)^2*IF(INT((DATE(2026+2,10,31)-F6)/365.25)=0,(12-DowntimeNew)/12,1),IF(I6="Option",G6*D6*1.025*(1+EscalatorInLease)^2,IF(I6="Market",Retention*G6*D6*(1+EscalatorInLease)^(2+M6)+(1-Retention)*H6*D6*(1+GrowthMarketRent)^2*IF(INT((DATE(2026+2,10,31)-F6)/365.25)=0,(12-DowntimeNew)/12,1),IF(I6="LeaseUp",H6*D6*(1+GrowthMarketRent)^2*IF(2=0,(12-DowntimeNew)/12,1),0)))))))),0) | Q6: =IFERROR(IF(I6="LeaseUp",H6*D6*(1+GrowthMarketRent)^3*IF(3=0,(12-DowntimeNew)/12,1),IF(F6="",0,IF(F6>=DATE(2027+3,4,30),G6*D6*(1+EscalatorInLease)^(3+M6),IF(F6<DATE(2026+3,5,1),IF(I6="Vacate",H6*D6*(1+GrowthMarketRent)^3*IF(INT((DATE(2026+3,10,31)-F6)/365.25)=0,(12-DowntimeNew)/12,1),IF(I6="Option",G6*D6*1.025*(1+EscalatorInLease)^3,IF(I6="Market",Retention*G6*D6*(1+EscalatorInLease)^(3+M6)+(1-Retention)*H6*D6*(1+GrowthMarketRent)^3*IF(INT((DATE(2026+3,10,31)-F6)/365.25)=0,(12-DowntimeNew)/12,1),IF(I6="LeaseUp",H6*D6*(1+GrowthMarketRent)^3*IF(3=0,(12-DowntimeNew)/12,1),0)))),((F6-DATE(2026+3,5,1))/365.25)*G6*D6*(1+EscalatorInLease)^(3+M6)+((DATE(2027+3,4,30)-F6)/365.25)*IF(I6="Vacate",H6*D6*(1+GrowthMarketRent)^3*IF(INT((DATE(2026+3,10,31)-F6)/365.25)=0,(12-DowntimeNew)/12,1),IF(I6="Option",G6*D6*1.025*(1+EscalatorInLease)^3,IF(I6="Market",Retention*G6*D6*(1+EscalatorInLease)^(3+M6)+(1-Retention)*H6*D6*(1+GrowthMarketRent)^3*IF(INT((DATE(2026+3,10,31)-F6)/365.25)=0,(12-DowntimeNew)/12,1),IF(I6="LeaseUp",H6*D6*(1+GrowthMarketRent)^3*IF(3=0,(12-DowntimeNew)/12,1),0)))))))),0) | R6: =IFERROR(IF(I6="LeaseUp",H6*D6*(1+GrowthMarketRent)^4*IF(4=0,(12-DowntimeNew)/12,1),IF(F6="",0,IF(F6>=DATE(2027+4,4,30),G6*D6*(1+EscalatorInLease)^(4+M6),IF(F6<DATE(2026+4,5,1),IF(I6="Vacate",H6*D6*(1+GrowthMarketRent)^4*IF(INT((DATE(2026+4,10,31)-F6)/365.25)=0,(12-DowntimeNew)/12,1),IF(I6="Option",G6*D6*1.025*(1+EscalatorInLease)^4,IF(I6="Market",Retention*G6*D6*(1+EscalatorInLease)^(4+M6)+(1-Retention)*H6*D6*(1+GrowthMarketRent)^4*IF(INT((DATE(2026+4,10,31)-F6)/365.25)=0,(12-DowntimeNew)/12,1),IF(I6="LeaseUp",H6*D6*(1+GrowthMarketRent)^4*IF(4=0,(12-DowntimeNew)/12,1),0)))),((F6-DATE(2026+4,5,1))/365.25)*G6*D6*(1+EscalatorInLease)^(4+M6)+((DATE(2027+4,4,30)-F6)/365.25)*IF(I6="Vacate",H6*D6*(1+GrowthMarketRent)^4*IF(INT((DATE(2026+4,10,31)-F6)/365.25)=0,(12-DowntimeNew)/12,1),IF(I6="Option",G6*D6*1.025*(1+EscalatorInLease)^4,IF(I6="Market",Retention*G6*D6*(1+EscalatorInLease)^(4+M6)+(1-Retention)*H6*D6*(1+GrowthMarketRent)^4*IF(INT((DATE(2026+4,10,31)-F6)/365.25)=0,(12-DowntimeNew)/12,1),IF(I6="LeaseUp",H6*D6*(1+GrowthMarketRent)^4*IF(4=0,(12-DowntimeNew)/12,1),0)))))))),0) | S6: =IFERROR(IF(I6="LeaseUp",H6*D6*(1+GrowthMarketRent)^5*IF(5=0,(12-DowntimeNew)/12,1),IF(F6="",0,IF(F6>=DATE(2027+5,4,30),G6*D6*(1+EscalatorInLease)^(5+M6),IF(F6<DATE(2026+5,5,1),IF(I6="Vacate",H6*D6*(1+GrowthMarketRent)^5*IF(INT((DATE(2026+5,10,31)-F6)/365.25)=0,(12-DowntimeNew)/12,1),IF(I6="Option",G6*D6*1.025*(1+EscalatorInLease)^5,IF(I6="Market",Retention*G6*D6*(1+EscalatorInLease)^(5+M6)+(1-Retention)*H6*D6*(1+GrowthMarketRent)^5*IF(INT((DATE(2026+5,10,31)-F6)/365.25)=0,(12-DowntimeNew)/12,1),IF(I6="LeaseUp",H6*D6*(1+GrowthMarketRent)^5*IF(5=0,(12-DowntimeNew)/12,1),0)))),((F6-DATE(2026+5,5,1))/365.25)*G6*D6*(1+EscalatorInLease)^(5+M6)+((DATE(2027+5,4,30)-F6)/365.25)*IF(I6="Vacate",H6*D6*(1+GrowthMarketRent)^5*IF(INT((DATE(2026+5,10,31)-F6)/365.25)=0,(12-DowntimeNew)/12,1),IF(I6="Option",G6*D6*1.025*(1+EscalatorInLease)^5,IF(I6="Market",Retention*G6*D6*(1+EscalatorInLease)^(5+M6)+(1-Retention)*H6*D6*(1+GrowthMarketRent)^5*IF(INT((DATE(2026+5,10,31)-F6)/365.25)=0,(12-DowntimeNew)/12,1),IF(I6="LeaseUp",H6*D6*(1+GrowthMarketRent)^5*IF(5=0,(12-DowntimeNew)/12,1),0)))))))),0) | T6: =IFERROR(IF(I6="LeaseUp",H6*D6*(1+GrowthMarketRent)^6*IF(6=0,(12-DowntimeNew)/12,1),IF(F6="",0,IF(F6>=DATE(2027+6,4,30),G6*D6*(1+EscalatorInLease)^(6+M6),IF(F6<DATE(2026+6,5,1),IF(I6="Vacate",H6*D6*(1+GrowthMarketRent)^6*IF(INT((DATE(2026+6,10,31)-F6)/365.25)=0,(12-DowntimeNew)/12,1),IF(I6="Option",G6*D6*1.025*(1+EscalatorInLease)^6,IF(I6="Market",Retention*G6*D6*(1+EscalatorInLease)^(6+M6)+(1-Retention)*H6*D6*(1+GrowthMarketRent)^6*IF(INT((DATE(2026+6,10,31)-F6)/365.25)=0,(12-DowntimeNew)/12,1),IF(I6="LeaseUp",H6*D6*(1+GrowthMarketRent)^6*IF(6=0,(12-DowntimeNew)/12,1),0)))),((F6-DATE(2026+6,5,1))/365.25)*G6*D6*(1+EscalatorInLease)^(6+M6)+((DATE(2027+6,4,30)-F6)/365.25)*IF(I6="Vacate",H6*D6*(1+GrowthMarketRent)^6*IF(INT((DATE(2026+6,10,31)-F6)/365.25)=0,(12-DowntimeNew)/12,1),IF(I6="Option",G6*D6*1.025*(1+EscalatorInLease)^6,IF(I6="Market",Retention*G6*D6*(1+EscalatorInLease)^(6+M6)+(1-Retention)*H6*D6*(1+GrowthMarketRent)^6*IF(INT((DATE(2026+6,10,31)-F6)/365.25)=0,(12-DowntimeNew)/12,1),IF(I6="LeaseUp",H6*D6*(1+GrowthMarketRent)^6*IF(6=0,(12-DowntimeNew)/12,1),0)))))))),0) | U6: =IFERROR(IF(I6="LeaseUp",H6*D6*(1+GrowthMarketRent)^7*IF(7=0,(12-DowntimeNew)/12,1),IF(F6="",0,IF(F6>=DATE(2027+7,4,30),G6*D6*(1+EscalatorInLease)^(7+M6),IF(F6<DATE(2026+7,5,1),IF(I6="Vacate",H6*D6*(1+GrowthMarketRent)^7*IF(INT((DATE(2026+7,10,31)-F6)/365.25)=0,(12-DowntimeNew)/12,1),IF(I6="Option",G6*D6*1.025*(1+EscalatorInLease)^7,IF(I6="Market",Retention*G6*D6*(1+EscalatorInLease)^(7+M6)+(1-Retention)*H6*D6*(1+GrowthMarketRent)^7*IF(INT((DATE(2026+7,10,31)-F6)/365.25)=0,(12-DowntimeNew)/12,1),IF(I6="LeaseUp",H6*D6*(1+GrowthMarketRent)^7*IF(7=0,(12-DowntimeNew)/12,1),0)))),((F6-DATE(2026+7,5,1))/365.25)*G6*D6*(1+EscalatorInLease)^(7+M6)+((DATE(2027+7,4,30)-F6)/365.25)*IF(I6="Vacate",H6*D6*(1+GrowthMarketRent)^7*IF(INT((DATE(2026+7,10,31)-F6)/365.25)=0,(12-DowntimeNew)/12,1),IF(I6="Option",G6*D6*1.025*(1+EscalatorInLease)^7,IF(I6="Market",Retention*G6*D6*(1+EscalatorInLease)^(7+M6)+(1-Retention)*H6*D6*(1+GrowthMarketRent)^7*IF(INT((DATE(2026+7,10,31)-F6)/365.25)=0,(12-DowntimeNew)/12,1),IF(I6="LeaseUp",H6*D6*(1+GrowthMarketRent)^7*IF(7=0,(12-DowntimeNew)/12,1),0)))))))),0) | V6: =IFERROR(IF(I6="LeaseUp",H6*D6*(1+GrowthMarketRent)^8*IF(8=0,(12-DowntimeNew)/12,1),IF(F6="",0,IF(F6>=DATE(2027+8,4,30),G6*D6*(1+EscalatorInLease)^(8+M6),IF(F6<DATE(2026+8,5,1),IF(I6="Vacate",H6*D6*(1+GrowthMarketRent)^8*IF(INT((DATE(2026+8,10,31)-F6)/365.25)=0,(12-DowntimeNew)/12,1),IF(I6="Option",G6*D6*1.025*(1+EscalatorInLease)^8,IF(I6="Market",Retention*G6*D6*(1+EscalatorInLease)^(8+M6)+(1-Retention)*H6*D6*(1+GrowthMarketRent)^8*IF(INT((DATE(2026+8,10,31)-F6)/365.25)=0,(12-DowntimeNew)/12,1),IF(I6="LeaseUp",H6*D6*(1+GrowthMarketRent)^8*IF(8=0,(12-DowntimeNew)/12,1),0)))),((F6-DATE(2026+8,5,1))/365.25)*G6*D6*(1+EscalatorInLease)^(8+M6)+((DATE(2027+8,4,30)-F6)/365.25)*IF(I6="Vacate",H6*D6*(1+GrowthMarketRent)^8*IF(INT((DATE(2026+8,10,31)-F6)/365.25)=0,(12-DowntimeNew)/12,1),IF(I6="Option",G6*D6*1.025*(1+EscalatorInLease)^8,IF(I6="Market",Retention*G6*D6*(1+EscalatorInLease)^(8+M6)+(1-Retention)*H6*D6*(1+GrowthMarketRent)^8*IF(INT((DATE(2026+8,10,31)-F6)/365.25)=0,(12-DowntimeNew)/12,1),IF(I6="LeaseUp",H6*D6*(1+GrowthMarketRent)^8*IF(8=0,(12-DowntimeNew)/12,1),0)))))))),0) | W6: =IFERROR(IF(I6="LeaseUp",H6*D6*(1+GrowthMarketRent)^9*IF(9=0,(12-DowntimeNew)/12,1),IF(F6="",0,IF(F6>=DATE(2027+9,4,30),G6*D6*(1+EscalatorInLease)^(9+M6),IF(F6<DATE(2026+9,5,1),IF(I6="Vacate",H6*D6*(1+GrowthMarketRent)^9*IF(INT((DATE(2026+9,10,31)-F6)/365.25)=0,(12-DowntimeNew)/12,1),IF(I6="Option",G6*D6*1.025*(1+EscalatorInLease)^9,IF(I6="Market",Retention*G6*D6*(1+EscalatorInLease)^(9+M6)+(1-Retention)*H6*D6*(1+GrowthMarketRent)^9*IF(INT((DATE(2026+9,10,31)-F6)/365.25)=0,(12-DowntimeNew)/12,1),IF(I6="LeaseUp",H6*D6*(1+GrowthMarketRent)^9*IF(9=0,(12-DowntimeNew)/12,1),0)))),((F6-DATE(2026+9,5,1))/365.25)*G6*D6*(1+EscalatorInLease)^(9+M6)+((DATE(2027+9,4,30)-F6)/365.25)*IF(I6="Vacate",H6*D6*(1+GrowthMarketRent)^9*IF(INT((DATE(2026+9,10,31)-F6)/365.25)=0,(12-DowntimeNew)/12,1),IF(I6="Option",G6*D6*1.025*(1+EscalatorInLease)^9,IF(I6="Market",Retention*G6*D6*(1+EscalatorInLease)^(9+M6)+(1-Retention)*H6*D6*(1+GrowthMarketRent)^9*IF(INT((DATE(2026+9,10,31)-F6)/365.25)=0,(12-DowntimeNew)/12,1),IF(I6="LeaseUp",H6*D6*(1+GrowthMarketRent)^9*IF(9=0,(12-DowntimeNew)/12,1),0)))))))),0) | X6: =IFERROR(IF(I6="LeaseUp",H6*D6*(1+GrowthMarketRent)^10*IF(10=0,(12-DowntimeNew)/12,1),IF(F6="",0,IF(F6>=DATE(2027+10,4,30),G6*D6*(1+EscalatorInLease)^(10+M6),IF(F6<DATE(2026+10,5,1),IF(I6="Vacate",H6*D6*(1+GrowthMarketRent)^10*IF(INT((DATE(2026+10,10,31)-F6)/365.25)=0,(12-DowntimeNew)/12,1),IF(I6="Option",G6*D6*1.025*(1+EscalatorInLease)^10,IF(I6="Market",Retention*G6*D6*(1+EscalatorInLease)^(10+M6)+(1-Retention)*H6*D6*(1+GrowthMarketRent)^10*IF(INT((DATE(2026+10,10,31)-F6)/365.25)=0,(12-DowntimeNew)/12,1),IF(I6="LeaseUp",H6*D6*(1+GrowthMarketRent)^10*IF(10=0,(12-DowntimeNew)/12,1),0)))),((F6-DATE(2026+10,5,1))/365.25)*G6*D6*(1+EscalatorInLease)^(10+M6)+((DATE(2027+10,4,30)-F6)/365.25)*IF(I6="Vacate",H6*D6*(1+GrowthMarketRent)^10*IF(INT((DATE(2026+10,10,31)-F6)/365.25)=0,(12-DowntimeNew)/12,1),IF(I6="Option",G6*D6*1.025*(1+EscalatorInLease)^10,IF(I6="Market",Retention*G6*D6*(1+EscalatorInLease)^(10+M6)+(1-Retention)*H6*D6*(1+GrowthMarketRent)^10*IF(INT((DATE(2026+10,10,31)-F6)/365.25)=0,(12-DowntimeNew)/12,1),IF(I6="LeaseUp",H6*D6*(1+GrowthMarketRent)^10*IF(10=0,(12-DowntimeNew)/12,1),0)))))))),0) | Y6: =IFERROR(IF(AND(I6="LeaseUp",0=0),(IF(I6="Vacate",TINew*D6,IF(I6="Market",Retention*TIRenewal*D6+(1-Retention)*TINew*D6,IF(I6="LeaseUp",TINew*D6,IF(I6="Option",TIRenewal*D6,0)))))+(IF(I6="Vacate",LCNew*H6*D6*(1+GrowthMarketRent)^0,IF(I6="Market",Retention*LCRenewal*H6*D6*(1+GrowthMarketRent)^0+(1-Retention)*LCNew*H6*D6*(1+GrowthMarketRent)^0,IF(I6="LeaseUp",LCNew*H6*D6*(1+GrowthMarketRent)^0,IF(I6="Option",LCRenewal*H6*D6*(1+GrowthMarketRent)^0,0))))),IF(F6="",0,IF(AND(F6>=DATE(2026+0,5,1),F6<=DATE(2027+0,4,30)),(IF(I6="Vacate",TINew*D6,IF(I6="Market",Retention*TIRenewal*D6+(1-Retention)*TINew*D6,IF(I6="LeaseUp",TINew*D6,IF(I6="Option",TIRenewal*D6,0)))))+(IF(I6="Vacate",LCNew*H6*D6*(1+GrowthMarketRent)^0,IF(I6="Market",Retention*LCRenewal*H6*D6*(1+GrowthMarketRent)^0+(1-Retention)*LCNew*H6*D6*(1+GrowthMarketRent)^0,IF(I6="LeaseUp",LCNew*H6*D6*(1+GrowthMarketRent)^0,IF(I6="Option",LCRenewal*H6*D6*(1+GrowthMarketRent)^0,0))))),0))),0) | Z6: =IFERROR(IF(AND(I6="LeaseUp",1=0),(IF(I6="Vacate",TINew*D6,IF(I6="Market",Retention*TIRenewal*D6+(1-Retention)*TINew*D6,IF(I6="LeaseUp",TINew*D6,IF(I6="Option",TIRenewal*D6,0)))))+(IF(I6="Vacate",LCNew*H6*D6*(1+GrowthMarketRent)^1,IF(I6="Market",Retention*LCRenewal*H6*D6*(1+GrowthMarketRent)^1+(1-Retention)*LCNew*H6*D6*(1+GrowthMarketRent)^1,IF(I6="LeaseUp",LCNew*H6*D6*(1+GrowthMarketRent)^1,IF(I6="Option",LCRenewal*H6*D6*(1+GrowthMarketRent)^1,0))))),IF(F6="",0,IF(AND(F6>=DATE(2026+1,5,1),F6<=DATE(2027+1,4,30)),(IF(I6="Vacate",TINew*D6,IF(I6="Market",Retention*TIRenewal*D6+(1-Retention)*TINew*D6,IF(I6="LeaseUp",TINew*D6,IF(I6="Option",TIRenewal*D6,0)))))+(IF(I6="Vacate",LCNew*H6*D6*(1+GrowthMarketRent)^1,IF(I6="Market",Retention*LCRenewal*H6*D6*(1+GrowthMarketRent)^1+(1-Retention)*LCNew*H6*D6*(1+GrowthMarketRent)^1,IF(I6="LeaseUp",LCNew*H6*D6*(1+GrowthMarketRent)^1,IF(I6="Option",LCRenewal*H6*D6*(1+GrowthMarketRent)^1,0))))),0))),0) | AA6: =IFERROR(IF(AND(I6="LeaseUp",2=0),(IF(I6="Vacate",TINew*D6,IF(I6="Market",Retention*TIRenewal*D6+(1-Retention)*TINew*D6,IF(I6="LeaseUp",TINew*D6,IF(I6="Option",TIRenewal*D6,0)))))+(IF(I6="Vacate",LCNew*H6*D6*(1+GrowthMarketRent)^2,IF(I6="Market",Retention*LCRenewal*H6*D6*(1+GrowthMarketRent)^2+(1-Retention)*LCNew*H6*D6*(1+GrowthMarketRent)^2,IF(I6="LeaseUp",LCNew*H6*D6*(1+GrowthMarketRent)^2,IF(I6="Option",LCRenewal*H6*D6*(1+GrowthMarketRent)^2,0))))),IF(F6="",0,IF(AND(F6>=DATE(2026+2,5,1),F6<=DATE(2027+2,4,30)),(IF(I6="Vacate",TINew*D6,IF(I6="Market",Retention*TIRenewal*D6+(1-Retention)*TINew*D6,IF(I6="LeaseUp",TINew*D6,IF(I6="Option",TIRenewal*D6,0)))))+(IF(I6="Vacate",LCNew*H6*D6*(1+GrowthMarketRent)^2,IF(I6="Market",Retention*LCRenewal*H6*D6*(1+GrowthMarketRent)^2+(1-Retention)*LCNew*H6*D6*(1+GrowthMarketRent)^2,IF(I6="LeaseUp",LCNew*H6*D6*(1+GrowthMarketRent)^2,IF(I6="Option",LCRenewal*H6*D6*(1+GrowthMarketRent)^2,0))))),0))),0) | AB6: =IFERROR(IF(AND(I6="LeaseUp",3=0),(IF(I6="Vacate",TINew*D6,IF(I6="Market",Retention*TIRenewal*D6+(1-Retention)*TINew*D6,IF(I6="LeaseUp",TINew*D6,IF(I6="Option",TIRenewal*D6,0)))))+(IF(I6="Vacate",LCNew*H6*D6*(1+GrowthMarketRent)^3,IF(I6="Market",Retention*LCRenewal*H6*D6*(1+GrowthMarketRent)^3+(1-Retention)*LCNew*H6*D6*(1+GrowthMarketRent)^3,IF(I6="LeaseUp",LCNew*H6*D6*(1+GrowthMarketRent)^3,IF(I6="Option",LCRenewal*H6*D6*(1+GrowthMarketRent)^3,0))))),IF(F6="",0,IF(AND(F6>=DATE(2026+3,5,1),F6<=DATE(2027+3,4,30)),(IF(I6="Vacate",TINew*D6,IF(I6="Market",Retention*TIRenewal*D6+(1-Retention)*TINew*D6,IF(I6="LeaseUp",TINew*D6,IF(I6="Option",TIRenewal*D6,0)))))+(IF(I6="Vacate",LCNew*H6*D6*(1+GrowthMarketRent)^3,IF(I6="Market",Retention*LCRenewal*H6*D6*(1+GrowthMarketRent)^3+(1-Retention)*LCNew*H6*D6*(1+GrowthMarketRent)^3,IF(I6="LeaseUp",LCNew*H6*D6*(1+GrowthMarketRent)^3,IF(I6="Option",LCRenewal*H6*D6*(1+GrowthMarketRent)^3,0))))),0))),0) | AC6: =IFERROR(IF(AND(I6="LeaseUp",4=0),(IF(I6="Vacate",TINew*D6,IF(I6="Market",Retention*TIRenewal*D6+(1-Retention)*TINew*D6,IF(I6="LeaseUp",TINew*D6,IF(I6="Option",TIRenewal*D6,0)))))+(IF(I6="Vacate",LCNew*H6*D6*(1+GrowthMarketRent)^4,IF(I6="Market",Retention*LCRenewal*H6*D6*(1+GrowthMarketRent)^4+(1-Retention)*LCNew*H6*D6*(1+GrowthMarketRent)^4,IF(I6="LeaseUp",LCNew*H6*D6*(1+GrowthMarketRent)^4,IF(I6="Option",LCRenewal*H6*D6*(1+GrowthMarketRent)^4,0))))),IF(F6="",0,IF(AND(F6>=DATE(2026+4,5,1),F6<=DATE(2027+4,4,30)),(IF(I6="Vacate",TINew*D6,IF(I6="Market",Retention*TIRenewal*D6+(1-Retention)*TINew*D6,IF(I6="LeaseUp",TINew*D6,IF(I6="Option",TIRenewal*D6,0)))))+(IF(I6="Vacate",LCNew*H6*D6*(1+GrowthMarketRent)^4,IF(I6="Market",Retention*LCRenewal*H6*D6*(1+GrowthMarketRent)^4+(1-Retention)*LCNew*H6*D6*(1+GrowthMarketRent)^4,IF(I6="LeaseUp",LCNew*H6*D6*(1+GrowthMarketRent)^4,IF(I6="Option",LCRenewal*H6*D6*(1+GrowthMarketRent)^4,0))))),0))),0) | AD6: =IFERROR(IF(AND(I6="LeaseUp",5=0),(IF(I6="Vacate",TINew*D6,IF(I6="Market",Retention*TIRenewal*D6+(1-Retention)*TINew*D6,IF(I6="LeaseUp",TINew*D6,IF(I6="Option",TIRenewal*D6,0)))))+(IF(I6="Vacate",LCNew*H6*D6*(1+GrowthMarketRent)^5,IF(I6="Market",Retention*LCRenewal*H6*D6*(1+GrowthMarketRent)^5+(1-Retention)*LCNew*H6*D6*(1+GrowthMarketRent)^5,IF(I6="LeaseUp",LCNew*H6*D6*(1+GrowthMarketRent)^5,IF(I6="Option",LCRenewal*H6*D6*(1+GrowthMarketRent)^5,0))))),IF(F6="",0,IF(AND(F6>=DATE(2026+5,5,1),F6<=DATE(2027+5,4,30)),(IF(I6="Vacate",TINew*D6,IF(I6="Market",Retention*TIRenewal*D6+(1-Retention)*TINew*D6,IF(I6="LeaseUp",TINew*D6,IF(I6="Option",TIRenewal*D6,0)))))+(IF(I6="Vacate",LCNew*H6*D6*(1+GrowthMarketRent)^5,IF(I6="Market",Retention*LCRenewal*H6*D6*(1+GrowthMarketRent)^5+(1-Retention)*LCNew*H6*D6*(1+GrowthMarketRent)^5,IF(I6="LeaseUp",LCNew*H6*D6*(1+GrowthMarketRent)^5,IF(I6="Option",LCRenewal*H6*D6*(1+GrowthMarketRent)^5,0))))),0))),0) | AE6: =IFERROR(IF(AND(I6="LeaseUp",6=0),(IF(I6="Vacate",TINew*D6,IF(I6="Market",Retention*TIRenewal*D6+(1-Retention)*TINew*D6,IF(I6="LeaseUp",TINew*D6,IF(I6="Option",TIRenewal*D6,0)))))+(IF(I6="Vacate",LCNew*H6*D6*(1+GrowthMarketRent)^6,IF(I6="Market",Retention*LCRenewal*H6*D6*(1+GrowthMarketRent)^6+(1-Retention)*LCNew*H6*D6*(1+GrowthMarketRent)^6,IF(I6="LeaseUp",LCNew*H6*D6*(1+GrowthMarketRent)^6,IF(I6="Option",LCRenewal*H6*D6*(1+GrowthMarketRent)^6,0))))),IF(F6="",0,IF(AND(F6>=DATE(2026+6,5,1),F6<=DATE(2027+6,4,30)),(IF(I6="Vacate",TINew*D6,IF(I6="Market",Retention*TIRenewal*D6+(1-Retention)*TINew*D6,IF(I6="LeaseUp",TINew*D6,IF(I6="Option",TIRenewal*D6,0)))))+(IF(I6="Vacate",LCNew*H6*D6*(1+GrowthMarketRent)^6,IF(I6="Market",Retention*LCRenewal*H6*D6*(1+GrowthMarketRent)^6+(1-Retention)*LCNew*H6*D6*(1+GrowthMarketRent)^6,IF(I6="LeaseUp",LCNew*H6*D6*(1+GrowthMarketRent)^6,IF(I6="Option",LCRenewal*H6*D6*(1+GrowthMarketRent)^6,0))))),0))),0) | AF6: =IFERROR(IF(AND(I6="LeaseUp",7=0),(IF(I6="Vacate",TINew*D6,IF(I6="Market",Retention*TIRenewal*D6+(1-Retention)*TINew*D6,IF(I6="LeaseUp",TINew*D6,IF(I6="Option",TIRenewal*D6,0)))))+(IF(I6="Vacate",LCNew*H6*D6*(1+GrowthMarketRent)^7,IF(I6="Market",Retention*LCRenewal*H6*D6*(1+GrowthMarketRent)^7+(1-Retention)*LCNew*H6*D6*(1+GrowthMarketRent)^7,IF(I6="LeaseUp",LCNew*H6*D6*(1+GrowthMarketRent)^7,IF(I6="Option",LCRenewal*H6*D6*(1+GrowthMarketRent)^7,0))))),IF(F6="",0,IF(AND(F6>=DATE(2026+7,5,1),F6<=DATE(2027+7,4,30)),(IF(I6="Vacate",TINew*D6,IF(I6="Market",Retention*TIRenewal*D6+(1-Retention)*TINew*D6,IF(I6="LeaseUp",TINew*D6,IF(I6="Option",TIRenewal*D6,0)))))+(IF(I6="Vacate",LCNew*H6*D6*(1+GrowthMarketRent)^7,IF(I6="Market",Retention*LCRenewal*H6*D6*(1+GrowthMarketRent)^7+(1-Retention)*LCNew*H6*D6*(1+GrowthMarketRent)^7,IF(I6="LeaseUp",LCNew*H6*D6*(1+GrowthMarketRent)^7,IF(I6="Option",LCRenewal*H6*D6*(1+GrowthMarketRent)^7,0))))),0))),0) | AG6: =IFERROR(IF(AND(I6="LeaseUp",8=0),(IF(I6="Vacate",TINew*D6,IF(I6="Market",Retention*TIRenewal*D6+(1-Retention)*TINew*D6,IF(I6="LeaseUp",TINew*D6,IF(I6="Option",TIRenewal*D6,0)))))+(IF(I6="Vacate",LCNew*H6*D6*(1+GrowthMarketRent)^8,IF(I6="Market",Retention*LCRenewal*H6*D6*(1+GrowthMarketRent)^8+(1-Retention)*LCNew*H6*D6*(1+GrowthMarketRent)^8,IF(I6="LeaseUp",LCNew*H6*D6*(1+GrowthMarketRent)^8,IF(I6="Option",LCRenewal*H6*D6*(1+GrowthMarketRent)^8,0))))),IF(F6="",0,IF(AND(F6>=DATE(2026+8,5,1),F6<=DATE(2027+8,4,30)),(IF(I6="Vacate",TINew*D6,IF(I6="Market",Retention*TIRenewal*D6+(1-Retention)*TINew*D6,IF(I6="LeaseUp",TINew*D6,IF(I6="Option",TIRenewal*D6,0)))))+(IF(I6="Vacate",LCNew*H6*D6*(1+GrowthMarketRent)^8,IF(I6="Market",Retention*LCRenewal*H6*D6*(1+GrowthMarketRent)^8+(1-Retention)*LCNew*H6*D6*(1+GrowthMarketRent)^8,IF(I6="LeaseUp",LCNew*H6*D6*(1+GrowthMarketRent)^8,IF(I6="Option",LCRenewal*H6*D6*(1+GrowthMarketRent)^8,0))))),0))),0) | AH6: =IFERROR(IF(AND(I6="LeaseUp",9=0),(IF(I6="Vacate",TINew*D6,IF(I6="Market",Retention*TIRenewal*D6+(1-Retention)*TINew*D6,IF(I6="LeaseUp",TINew*D6,IF(I6="Option",TIRenewal*D6,0)))))+(IF(I6="Vacate",LCNew*H6*D6*(1+GrowthMarketRent)^9,IF(I6="Market",Retention*LCRenewal*H6*D6*(1+GrowthMarketRent)^9+(1-Retention)*LCNew*H6*D6*(1+GrowthMarketRent)^9,IF(I6="LeaseUp",LCNew*H6*D6*(1+GrowthMarketRent)^9,IF(I6="Option",LCRenewal*H6*D6*(1+GrowthMarketRent)^9,0))))),IF(F6="",0,IF(AND(F6>=DATE(2026+9,5,1),F6<=DATE(2027+9,4,30)),(IF(I6="Vacate",TINew*D6,IF(I6="Market",Retention*TIRenewal*D6+(1-Retention)*TINew*D6,IF(I6="LeaseUp",TINew*D6,IF(I6="Option",TIRenewal*D6,0)))))+(IF(I6="Vacate",LCNew*H6*D6*(1+GrowthMarketRent)^9,IF(I6="Market",Retention*LCRenewal*H6*D6*(1+GrowthMarketRent)^9+(1-Retention)*LCNew*H6*D6*(1+GrowthMarketRent)^9,IF(I6="LeaseUp",LCNew*H6*D6*(1+GrowthMarketRent)^9,IF(I6="Option",LCRenewal*H6*D6*(1+GrowthMarketRent)^9,0))))),0))),0) | AI6: =IFERROR(IF(AND(I6="LeaseUp",10=0),(IF(I6="Vacate",TINew*D6,IF(I6="Market",Retention*TIRenewal*D6+(1-Retention)*TINew*D6,IF(I6="LeaseUp",TINew*D6,IF(I6="Option",TIRenewal*D6,0)))))+(IF(I6="Vacate",LCNew*H6*D6*(1+GrowthMarketRent)^10,IF(I6="Market",Retention*LCRenewal*H6*D6*(1+GrowthMarketRent)^10+(1-Retention)*LCNew*H6*D6*(1+GrowthMarketRent)^10,IF(I6="LeaseUp",LCNew*H6*D6*(1+GrowthMarketRent)^10,IF(I6="Option",LCRenewal*H6*D6*(1+GrowthMarketRent)^10,0))))),IF(F6="",0,IF(AND(F6>=DATE(2026+10,5,1),F6<=DATE(2027+10,4,30)),(IF(I6="Vacate",TINew*D6,IF(I6="Market",Retention*TIRenewal*D6+(1-Retention)*TINew*D6,IF(I6="LeaseUp",TINew*D6,IF(I6="Option",TIRenewal*D6,0)))))+(IF(I6="Vacate",LCNew*H6*D6*(1+GrowthMarketRent)^10,IF(I6="Market",Retention*LCRenewal*H6*D6*(1+GrowthMarketRent)^10+(1-Retention)*LCNew*H6*D6*(1+GrowthMarketRent)^10,IF(I6="LeaseUp",LCNew*H6*D6*(1+GrowthMarketRent)^10,IF(I6="Option",LCRenewal*H6*D6*(1+GrowthMarketRent)^10,0))))),0))),0)
